<!doctype html>
<html>
<head>
<meta charset="utf-8">
<meta http-equiv="X-UA-Compatible" content="IE=edge,chrome=1">
<meta name="viewport" content="width=device-width, initial-scale=1">
<title>RAST source code scanning summary</title>
<meta charset="UTF-8">
<meta name="viewport" content="width=device-width, initial-scale=1.0">
<link rel="stylesheet" href="css/bootstrap.min.css">
<script src="js/jquery-2.1.4.min.js" type="text/javascript"></script>
<script src="js/bootstrap.min.js"></script>
<link href="css/jquerysctipttop.css" rel="stylesheet" type="text/css">
<!-- INCLUDES -->
<link rel="stylesheet" href="css/bootstrap-table-expandable.css">
<script src="js/bootstrap-table-expandable.js"></script>
<style>
h2 {color: #7c795d; font-family: 'Trocchi', serif; font-size: 45px; font-weight: normal; line-height: 48px; margin: 0; text-align: center;   }
table.repo_table {
color:#fff;
font-family:Helvetica,Arial,sans-serif;
border-collapse: collapse;
padding:0 3px;
border-radius: 5px;
margin: 25px auto;
}

table.repo_table td, table.repo_table th {
height:30px;
transition:all 1.5s;
text-align:center;
padding: 5px 40px;
border: 2px solid #000;
width: 200px;
}

table.repo_table th {
background:#000;
font-weight:700;
}

table.repo_table tr td {
background:#fff;
color:#000;
}

table.repo_table tr td:hover {
background:#666;
color:#FFF;
font-weight:bold;
}
</style>
</head>
<body>



<div class="container">
<br>
<br>
<br>
<br>
  <h2>RAST Summary</h2>

<!--  <p><strong>Note:</strong> The <strong>data-parent</strong> attribute makes sure that all collapsible elements under the specified parent will be closed when one of the collapsible item is shown.</p>
<p>Demo for <a href="http://www.jankoatwarpspeed.com/post/2009/07/19/Expand-table-rows-with-jQuery-jExpand-plugin.aspx">Expand table rows with jQuery - jExpand plugin</a></p> -->

<table class="repo_table">
    <thead>
        <tr>
            <th>Rule Name</th>
            <th>Total Violations</th>
            
        </tr>
    </thead>
    <tbody>
<tr>
<td><a href="https://www.securecoding.cert.org/confluence/display/java/DCL00-J.+Prevent+class+initialization+cycles" target="_blank"> DCL00J</a></td>
<td>1</td>
 </tr>
<tr>
<td><a href="https://www.securecoding.cert.org/confluence/display/java/DCL01-J.+Do+not+reuse+public+identifiers+from+the+Java+Standard+Library" target="_blank"> DCL01-J</a></td>
<td>0</td>
 </tr>
<tr>
<td><a href="https://www.securecoding.cert.org/confluence/display/java/DCL02-J.+Do+not+modify+the+collection%27s+elements+during+an+enhanced+for+statement" target="_blank"> DCL02-J</a></td>
<td>0</td>
 </tr>
<tr>
<td><a href="https://www.securecoding.cert.org/confluence/display/java/EXP02-J.+Do+not+use+the+Object.equals%28%29+method+to+compare+two+arrays" target="_blank"> EXP02-J</a></td>
<td>0</td>
 </tr>
<tr>
<td><a href="https://www.securecoding.cert.org/confluence/display/java/ERR02-J.+Prevent+exceptions+while+logging+data" target="_blank"> ERR02-J</a></td>
<td>0</td>
 </tr>
<tr>
<td><a href="https://www.securecoding.cert.org/confluence/display/java/ERR04-J.+Do+not+complete+abruptly+from+a+finally+block" target="_blank"> ERR04-J</a></td>
<td>0</td>
 </tr>
<tr>
<td><a href="https://www.securecoding.cert.org/confluence/display/java/ERR05-J.+Do+not+let+checked+exceptions+escape+from+a+finally+block" target="_blank"> ERR05-J</a></td>
<td>55</td>
 </tr>
<tr>
<td><a href="https://www.securecoding.cert.org/confluence/display/java/ERR07-J.+Do+not+throw+RuntimeException%2C+Exception%2C+or+Throwable" target="_blank"> ERR07-J</a></td>
<td>1</td>
 </tr>
<tr>
<td><a href="https://www.securecoding.cert.org/confluence/display/java/ERR02-J.+Prevent+exceptions+while+logging+data" target="_blank"> ERR08-J</a></td>
<td>0</td>
 </tr>
<tr>
<td><a href="https://www.securecoding.cert.org/confluence/display/java/FIO02-J.+Detect+and+handle+file-related+errors" target="_blank"> FIO02-J</a></td>
<td>1</td>
 </tr>
<tr>
<td><a href="https://www.securecoding.cert.org/confluence/display/java/LCK01-J.+Do+not+synchronize+on+objects+that+may+be+reused" target="_blank"> LCK01-J</a></td>
<td>0</td>
 </tr>
<tr>
<td><a href="https://www.securecoding.cert.org/confluence/pages/viewpage.action?pageId=43647087" target="_blank"> LCK02-J</a></td>
<td>0</td>
 </tr>
<tr>
<td><a href="https://www.securecoding.cert.org/confluence/display/java/MET09-J.+Classes+that+define+an+equals%28%29+method+must+also+define+a+hashCode%28%29+method" target="_blank"> MET09-J</a></td>
<td>0</td>
 </tr>
<tr>
<td><a href="https://www.securecoding.cert.org/confluence/display/java/MSC00-J.+Use+SSLSocket+rather+than+Socket+for+secure+data+exchange" target="_blank"> MSC00-J</a></td>
<td>0</td>
 </tr>
<tr>
<td><a href="https://www.securecoding.cert.org/confluence/display/java/MSC01-J.+Do+not+use+an+empty+infinite+loop" target="_blank"> MSC01-J</a></td>
<td>0</td>
 </tr>
<tr>
<td><a href="https://www.securecoding.cert.org/confluence/display/java/MSC02-J.+Generate+strong+random+numbers" target="_blank"> MSC02-J</a></td>
<td>0</td>
 </tr>
<tr>
<td><a href="https://www.securecoding.cert.org/confluence/display/java/NUM07-J.+Do+not+attempt+comparisons+with+NaN" target="_blank"> NUM07-J</a></td>
<td>0</td>
 </tr>
<tr>
<td><a href="https://www.securecoding.cert.org/confluence/display/java/NUM09-J.+Do+not+use+floating-point+variables+as+loop+counters" target="_blank"> NUM09-J</a></td>
<td>0</td>
 </tr>
<tr>
<td><a href="https://www.securecoding.cert.org/confluence/display/java/NUM10-J.+Do+not+construct+BigDecimal+objects+from+floating-point+literals" target="_blank"> NUM10-J</a></td>
<td>0</td>
 </tr>
<tr>
<td><a href="https://www.securecoding.cert.org/confluence/display/java/OBJ09-J.+Compare+classes+and+not+class+names" target="_blank"> OBJ09-J</a></td>
<td>0</td>
 </tr>
<tr>
<td><a href="https://www.securecoding.cert.org/confluence/display/java/OBJ10-J.+Do+not+use+public+static+nonfinal+fields" target="_blank"> OBJ10-J</a></td>
<td>3</td>
 </tr>
<tr>
<td><a href="https://www.securecoding.cert.org/confluence/display/java/SER05-J.+Do+not+serialize+instances+of+inner+classes" target="_blank"> SER05-J</a></td>
<td>0</td>
 </tr>

 </tbody>
    </table> 
<br>
<hr noshade>
<br>
<h4 style="color:#660000;">Total 8 directories searched and 69 files scanned. Out of the above rules, 61 CERT violations are reported </h4>
<br>
<hr noshade>
<br>
<div style="text-align:center">  
     <button class="btn" data-toggle="collapse" data-target="#demo">View Detailed Report</button>
</div> 
<div id="demo" class="collapse">
<h4>Following files have secure coding violations </h4>
  <div class="panel-group" id="accordion">
    <div class="panel panel-default">
  
        <div class="panel panel-default">
      <div class="panel-heading">
        <h4 class="panel-title">
          <a data-toggle="collapse" data-parent="#accordion" href="#Loc2">AbstractSyncAdapter.java</a>
        </h4>
      </div>
      <div id="Loc2" class="panel-collapse collapse collapse">
        <div class="panel-body"> <table class="table table-hover table-expandable table-striped">
    <thead>
 <p>Location :<a href="/media/rahul/Education/Project/src/M/Sources/packages/apps/Exchange/src/com/android/exchange/adapter/AbstractSyncAdapter.java">/media/rahul/Education/Project/src/M/Sources/packages/apps/Exchange/src/com/android/exchange/adapter/AbstractSyncAdapter.java</a></p>

      <tr>
        <th>Rule</th>
        <th>Standard</th>
        <th>Line number</th>
        
      </tr>
    </thead>
    <tbody>
      
      
   	  <tr>
		<td>ERR07-J</td>
		<td>CERT</td>
		<td>273</td>
		<td><!--$001violation$001--></td>
	      </tr>
      

<tr>

      
        <td colspan="5">
 <h4>ERR07-J. Do not throw RuntimeException, Exception, or Throwable</h4>
     <p>Methods must not throw RuntimeException, Exception, or Throwable. Throwing a RuntimeException can lead to subtle errors; for example, a caller cannot examine the exception to determine why it was thrown and consequently cannot attempt recovery.
     <p>Methods must not throw RuntimeException, Exception, or Throwable. Throwing a RuntimeException can lead to subtle errors; for example, a caller cannot examine the exception to determine why it was thrown and consequently cannot attempt recovery.
</p>
        
        <p>In the given program line number <span style="color: red">273 </span> throws <span style="color: red">RuntimeException </span> </p> 
        <span style="color: #660000">  <h4>Non-compliant Solution</h4></span>
<p> The isCapitalized() method in this noncompliant code example accepts a string and returns true when the string consists of a capital letter followed by lowercase letters. The method also throws a RuntimeException when passed a null string argument. </p>
 <pre><code class="language-java"> 
boolean isCapitalized(String s) {
  if (s == null) {
    throw new RuntimeException("Null String");
  }
  if (s.equals("")) {
    return true;
  }
  String first = s.substring(0, 1);
  String rest = s.substring(1);
  return (first.equals(first.toUpperCase()) &&
          rest.equals(rest.toLowerCase()));
}
 </code></pre>
<span style="color:#00b33c"><h4>Compliant Solution</h4></span>
<p> This compliant solution throws NullPointerException to denote the specific exceptional condition</p>
 <pre><code class="language-java">
  boolean isCapitalized(String s) {
  if (s == null) {
    throw new NullPointerException();
  }
  if (s.equals("")) {
    return true;
  }
  String first = s.substring(0, 1);
  String rest = s.substring(1);
  return (first.equals(first.toUpperCase()) &&
          rest.equals(rest.toLowerCase()));
}</code></pre>
<h4>Additional information</h4>
          <ul>
            <li><a href="https://www.securecoding.cert.org/confluence/display/java/ERR07-J.+Do+not+throw+RuntimeException%2C+Exception%2C+or+Throwable" target="_blank">ERR07-J. Do not throw RuntimeException, Exception, or Throwable</a></li>
          </ul> 
          <h4>Related Guidelines</h4>
          <ul>
            <li><a href="http://cwe.mitre.org/data/definitions/397.html" target="_blank">CWE-397</a>, Declaration of Throws for Generic Exception</li>
          </ul></td>  </tr>
<!--$newtableblockattachhere-->
    </tbody>
  </table></div>
      </div>
    </div>

    
 
  <div class="panel panel-default">
      <div class="panel-heading">
        <h4 class="panel-title">
          <a data-toggle="collapse" data-parent="#accordion" href="#Loc5">CalendarSyncParser.java</a>
        </h4>
      </div>
      <div id="Loc5" class="panel-collapse collapse collapse">
        <div class="panel-body"> <table class="table table-hover table-expandable table-striped">
    <thead>
 <p>Location :<a href="/media/rahul/Education/Project/src/M/Sources/packages/apps/Exchange/src/com/android/exchange/adapter/CalendarSyncParser.java">/media/rahul/Education/Project/src/M/Sources/packages/apps/Exchange/src/com/android/exchange/adapter/CalendarSyncParser.java</a></p>

      <tr>
        <th>Rule</th>
        <th>Standard</th>
        <th>Line number</th>
        
      </tr>
    </thead>
    <tbody>
      
      
   	  <tr>
		<td>ERR05-J</td>
		<td>CERT</td>
		<td>205</td>
		<td><!--$001violation$001--></td>
	      </tr>
      

<tr>

      
        <td colspan="5">
 <h4>ERR05-J. Do not let checked exceptions escape from a finally block</h4>
     <p>Methods invoked from within a finally block can throw an exception. Failure to catch and handle such exceptions results in the abrupt termination of the entire try block. Abrupt termination causes any exception thrown in the try block to be lost, preventing any possible recovery method from handling that specific problem. </p>
        
        <p>In the given program line number <span style="color: red">205 </span> A method invocation <span style="color: red">c.close() </span> is present inside a finally block without a try-catch block </p> 
        <span style="color: #660000">  <h4>Non-compliant Solution</h4></span>
<p> This noncompliant code example contains a finally block that closes the reader object. The programmer incorrectly assumes that the statements in the finally block cannot throw exceptions and consequently fails to appropriately handle any exception that may arise. </p>
 <pre><code class="language-java"> 
 try {
      BufferedReader reader =
          new BufferedReader(new FileReader(some_file));
      try {
        // Do operations
      } finally {
        reader.close();
        // ... Other cleanup code ...
      }
    } catch (IOException x) {
      // Forward to handler
    }
 </code></pre>
<span style="color:#00b33c"><h4>Compliant Solution</h4></span>
<p>  This compliant solution encloses the close() method invocation in a try-catch block of its own within the finally block. Consequently, the potential IOException can be handled without allowing it to propagate further.t</p>
 <pre><code class="language-java"> 
  try {
      BufferedReader reader =
          new BufferedReader(new FileReader(some_file));
      try {
        // Do operations
      } finally {
        try {
          reader.close();
        } catch (IOException ie) {
          // Forward to handler
        }
        // ... Other cleanup code ...
      }
    } catch (IOException x) {
      // Forward to handler
    }
    </code></pre>
<h4>Additional information</h4>
          <ul>
            <li><a href="https://www.securecoding.cert.org/confluence/display/java/ERR05-J.+Do+not+let+checked+exceptions+escape+from+a+finally+block" target="_blank"> ERR05-J. Do not let checked exceptions escape from a finally block</a></li>
          </ul> 
          <h4>Related Guidelines</h4>
          <ul>
            <li><a href="http://cwe.mitre.org/data/definitions/703.html" target="_blank"> CWE-703,</a> Improper Check or Handling of Exceptional Conditions</li>
          <li><a href="http://cwe.mitre.org/data/definitions/248.html" target="_blank"> CWE-248,</a> Uncaught Exception</li>
          
          </ul></td>  </tr>
	  <tr>
		<td>ERR05-J</td>
		<td>CERT</td>
		<td>377</td>
		<td><!--$001violation$001--></td>
	      </tr>
      

<tr>

      
        <td colspan="5">
 <h4>ERR05-J. Do not let checked exceptions escape from a finally block</h4>
     <p>Methods invoked from within a finally block can throw an exception. Failure to catch and handle such exceptions results in the abrupt termination of the entire try block. Abrupt termination causes any exception thrown in the try block to be lost, preventing any possible recovery method from handling that specific problem. </p>
        
        <p>In the given program line number <span style="color: red">377 </span> A method invocation <span style="color: red">c.close() </span> is present inside a finally block without a try-catch block </p> 
        <span style="color: #660000">  <h4>Non-compliant Solution</h4></span>
<p> This noncompliant code example contains a finally block that closes the reader object. The programmer incorrectly assumes that the statements in the finally block cannot throw exceptions and consequently fails to appropriately handle any exception that may arise. </p>
 <pre><code class="language-java"> 
 try {
      BufferedReader reader =
          new BufferedReader(new FileReader(some_file));
      try {
        // Do operations
      } finally {
        reader.close();
        // ... Other cleanup code ...
      }
    } catch (IOException x) {
      // Forward to handler
    }
 </code></pre>
<span style="color:#00b33c"><h4>Compliant Solution</h4></span>
<p>  This compliant solution encloses the close() method invocation in a try-catch block of its own within the finally block. Consequently, the potential IOException can be handled without allowing it to propagate further.t</p>
 <pre><code class="language-java"> 
  try {
      BufferedReader reader =
          new BufferedReader(new FileReader(some_file));
      try {
        // Do operations
      } finally {
        try {
          reader.close();
        } catch (IOException ie) {
          // Forward to handler
        }
        // ... Other cleanup code ...
      }
    } catch (IOException x) {
      // Forward to handler
    }
    </code></pre>
<h4>Additional information</h4>
          <ul>
            <li><a href="https://www.securecoding.cert.org/confluence/display/java/ERR05-J.+Do+not+let+checked+exceptions+escape+from+a+finally+block" target="_blank"> ERR05-J. Do not let checked exceptions escape from a finally block</a></li>
          </ul> 
          <h4>Related Guidelines</h4>
          <ul>
            <li><a href="http://cwe.mitre.org/data/definitions/703.html" target="_blank"> CWE-703,</a> Improper Check or Handling of Exceptional Conditions</li>
          <li><a href="http://cwe.mitre.org/data/definitions/248.html" target="_blank"> CWE-248,</a> Uncaught Exception</li>
          
          </ul></td>  </tr>
	  <tr>
		<td>ERR05-J</td>
		<td>CERT</td>
		<td>1102</td>
		<td><!--$001violation$001--></td>
	      </tr>
      

<tr>

      
        <td colspan="5">
 <h4>ERR05-J. Do not let checked exceptions escape from a finally block</h4>
     <p>Methods invoked from within a finally block can throw an exception. Failure to catch and handle such exceptions results in the abrupt termination of the entire try block. Abrupt termination causes any exception thrown in the try block to be lost, preventing any possible recovery method from handling that specific problem. </p>
        
        <p>In the given program line number <span style="color: red">1102 </span> A method invocation <span style="color: red">c.close() </span> is present inside a finally block without a try-catch block </p> 
        <span style="color: #660000">  <h4>Non-compliant Solution</h4></span>
<p> This noncompliant code example contains a finally block that closes the reader object. The programmer incorrectly assumes that the statements in the finally block cannot throw exceptions and consequently fails to appropriately handle any exception that may arise. </p>
 <pre><code class="language-java"> 
 try {
      BufferedReader reader =
          new BufferedReader(new FileReader(some_file));
      try {
        // Do operations
      } finally {
        reader.close();
        // ... Other cleanup code ...
      }
    } catch (IOException x) {
      // Forward to handler
    }
 </code></pre>
<span style="color:#00b33c"><h4>Compliant Solution</h4></span>
<p>  This compliant solution encloses the close() method invocation in a try-catch block of its own within the finally block. Consequently, the potential IOException can be handled without allowing it to propagate further.t</p>
 <pre><code class="language-java"> 
  try {
      BufferedReader reader =
          new BufferedReader(new FileReader(some_file));
      try {
        // Do operations
      } finally {
        try {
          reader.close();
        } catch (IOException ie) {
          // Forward to handler
        }
        // ... Other cleanup code ...
      }
    } catch (IOException x) {
      // Forward to handler
    }
    </code></pre>
<h4>Additional information</h4>
          <ul>
            <li><a href="https://www.securecoding.cert.org/confluence/display/java/ERR05-J.+Do+not+let+checked+exceptions+escape+from+a+finally+block" target="_blank"> ERR05-J. Do not let checked exceptions escape from a finally block</a></li>
          </ul> 
          <h4>Related Guidelines</h4>
          <ul>
            <li><a href="http://cwe.mitre.org/data/definitions/703.html" target="_blank"> CWE-703,</a> Improper Check or Handling of Exceptional Conditions</li>
          <li><a href="http://cwe.mitre.org/data/definitions/248.html" target="_blank"> CWE-248,</a> Uncaught Exception</li>
          
          </ul></td>  </tr>
	  <tr>
		<td>ERR05-J</td>
		<td>CERT</td>
		<td>1210</td>
		<td><!--$001violation$001--></td>
	      </tr>
      

<tr>

      
        <td colspan="5">
 <h4>ERR05-J. Do not let checked exceptions escape from a finally block</h4>
     <p>Methods invoked from within a finally block can throw an exception. Failure to catch and handle such exceptions results in the abrupt termination of the entire try block. Abrupt termination causes any exception thrown in the try block to be lost, preventing any possible recovery method from handling that specific problem. </p>
        
        <p>In the given program line number <span style="color: red">1210 </span> A method invocation <span style="color: red">c.close() </span> is present inside a finally block without a try-catch block </p> 
        <span style="color: #660000">  <h4>Non-compliant Solution</h4></span>
<p> This noncompliant code example contains a finally block that closes the reader object. The programmer incorrectly assumes that the statements in the finally block cannot throw exceptions and consequently fails to appropriately handle any exception that may arise. </p>
 <pre><code class="language-java"> 
 try {
      BufferedReader reader =
          new BufferedReader(new FileReader(some_file));
      try {
        // Do operations
      } finally {
        reader.close();
        // ... Other cleanup code ...
      }
    } catch (IOException x) {
      // Forward to handler
    }
 </code></pre>
<span style="color:#00b33c"><h4>Compliant Solution</h4></span>
<p>  This compliant solution encloses the close() method invocation in a try-catch block of its own within the finally block. Consequently, the potential IOException can be handled without allowing it to propagate further.t</p>
 <pre><code class="language-java"> 
  try {
      BufferedReader reader =
          new BufferedReader(new FileReader(some_file));
      try {
        // Do operations
      } finally {
        try {
          reader.close();
        } catch (IOException ie) {
          // Forward to handler
        }
        // ... Other cleanup code ...
      }
    } catch (IOException x) {
      // Forward to handler
    }
    </code></pre>
<h4>Additional information</h4>
          <ul>
            <li><a href="https://www.securecoding.cert.org/confluence/display/java/ERR05-J.+Do+not+let+checked+exceptions+escape+from+a+finally+block" target="_blank"> ERR05-J. Do not let checked exceptions escape from a finally block</a></li>
          </ul> 
          <h4>Related Guidelines</h4>
          <ul>
            <li><a href="http://cwe.mitre.org/data/definitions/703.html" target="_blank"> CWE-703,</a> Improper Check or Handling of Exceptional Conditions</li>
          <li><a href="http://cwe.mitre.org/data/definitions/248.html" target="_blank"> CWE-248,</a> Uncaught Exception</li>
          
          </ul></td>  </tr>
<!--$newtableblockattachhere-->
    </tbody>
  </table></div>
      </div>
    </div>

    
 
  <div class="panel panel-default">
      <div class="panel-heading">
        <h4 class="panel-title">
          <a data-toggle="collapse" data-parent="#accordion" href="#Loc6">ContactsSyncParser.java</a>
        </h4>
      </div>
      <div id="Loc6" class="panel-collapse collapse collapse">
        <div class="panel-body"> <table class="table table-hover table-expandable table-striped">
    <thead>
 <p>Location :<a href="/media/rahul/Education/Project/src/M/Sources/packages/apps/Exchange/src/com/android/exchange/adapter/ContactsSyncParser.java">/media/rahul/Education/Project/src/M/Sources/packages/apps/Exchange/src/com/android/exchange/adapter/ContactsSyncParser.java</a></p>

      <tr>
        <th>Rule</th>
        <th>Standard</th>
        <th>Line number</th>
        
      </tr>
    </thead>
    <tbody>
      
      
   	  <tr>
		<td>ERR05-J</td>
		<td>CERT</td>
		<td>443</td>
		<td><!--$001violation$001--></td>
	      </tr>
      

<tr>

      
        <td colspan="5">
 <h4>ERR05-J. Do not let checked exceptions escape from a finally block</h4>
     <p>Methods invoked from within a finally block can throw an exception. Failure to catch and handle such exceptions results in the abrupt termination of the entire try block. Abrupt termination causes any exception thrown in the try block to be lost, preventing any possible recovery method from handling that specific problem. </p>
        
        <p>In the given program line number <span style="color: red">443 </span> A method invocation <span style="color: red">c.close() </span> is present inside a finally block without a try-catch block </p> 
        <span style="color: #660000">  <h4>Non-compliant Solution</h4></span>
<p> This noncompliant code example contains a finally block that closes the reader object. The programmer incorrectly assumes that the statements in the finally block cannot throw exceptions and consequently fails to appropriately handle any exception that may arise. </p>
 <pre><code class="language-java"> 
 try {
      BufferedReader reader =
          new BufferedReader(new FileReader(some_file));
      try {
        // Do operations
      } finally {
        reader.close();
        // ... Other cleanup code ...
      }
    } catch (IOException x) {
      // Forward to handler
    }
 </code></pre>
<span style="color:#00b33c"><h4>Compliant Solution</h4></span>
<p>  This compliant solution encloses the close() method invocation in a try-catch block of its own within the finally block. Consequently, the potential IOException can be handled without allowing it to propagate further.t</p>
 <pre><code class="language-java"> 
  try {
      BufferedReader reader =
          new BufferedReader(new FileReader(some_file));
      try {
        // Do operations
      } finally {
        try {
          reader.close();
        } catch (IOException ie) {
          // Forward to handler
        }
        // ... Other cleanup code ...
      }
    } catch (IOException x) {
      // Forward to handler
    }
    </code></pre>
<h4>Additional information</h4>
          <ul>
            <li><a href="https://www.securecoding.cert.org/confluence/display/java/ERR05-J.+Do+not+let+checked+exceptions+escape+from+a+finally+block" target="_blank"> ERR05-J. Do not let checked exceptions escape from a finally block</a></li>
          </ul> 
          <h4>Related Guidelines</h4>
          <ul>
            <li><a href="http://cwe.mitre.org/data/definitions/703.html" target="_blank"> CWE-703,</a> Improper Check or Handling of Exceptional Conditions</li>
          <li><a href="http://cwe.mitre.org/data/definitions/248.html" target="_blank"> CWE-248,</a> Uncaught Exception</li>
          
          </ul></td>  </tr>
	  <tr>
		<td>ERR05-J</td>
		<td>CERT</td>
		<td>494</td>
		<td><!--$001violation$001--></td>
	      </tr>
      

<tr>

      
        <td colspan="5">
 <h4>ERR05-J. Do not let checked exceptions escape from a finally block</h4>
     <p>Methods invoked from within a finally block can throw an exception. Failure to catch and handle such exceptions results in the abrupt termination of the entire try block. Abrupt termination causes any exception thrown in the try block to be lost, preventing any possible recovery method from handling that specific problem. </p>
        
        <p>In the given program line number <span style="color: red">494 </span> A method invocation <span style="color: red">c.close() </span> is present inside a finally block without a try-catch block </p> 
        <span style="color: #660000">  <h4>Non-compliant Solution</h4></span>
<p> This noncompliant code example contains a finally block that closes the reader object. The programmer incorrectly assumes that the statements in the finally block cannot throw exceptions and consequently fails to appropriately handle any exception that may arise. </p>
 <pre><code class="language-java"> 
 try {
      BufferedReader reader =
          new BufferedReader(new FileReader(some_file));
      try {
        // Do operations
      } finally {
        reader.close();
        // ... Other cleanup code ...
      }
    } catch (IOException x) {
      // Forward to handler
    }
 </code></pre>
<span style="color:#00b33c"><h4>Compliant Solution</h4></span>
<p>  This compliant solution encloses the close() method invocation in a try-catch block of its own within the finally block. Consequently, the potential IOException can be handled without allowing it to propagate further.t</p>
 <pre><code class="language-java"> 
  try {
      BufferedReader reader =
          new BufferedReader(new FileReader(some_file));
      try {
        // Do operations
      } finally {
        try {
          reader.close();
        } catch (IOException ie) {
          // Forward to handler
        }
        // ... Other cleanup code ...
      }
    } catch (IOException x) {
      // Forward to handler
    }
    </code></pre>
<h4>Additional information</h4>
          <ul>
            <li><a href="https://www.securecoding.cert.org/confluence/display/java/ERR05-J.+Do+not+let+checked+exceptions+escape+from+a+finally+block" target="_blank"> ERR05-J. Do not let checked exceptions escape from a finally block</a></li>
          </ul> 
          <h4>Related Guidelines</h4>
          <ul>
            <li><a href="http://cwe.mitre.org/data/definitions/703.html" target="_blank"> CWE-703,</a> Improper Check or Handling of Exceptional Conditions</li>
          <li><a href="http://cwe.mitre.org/data/definitions/248.html" target="_blank"> CWE-248,</a> Uncaught Exception</li>
          
          </ul></td>  </tr>
	  <tr>
		<td>ERR05-J</td>
		<td>CERT</td>
		<td>583</td>
		<td><!--$001violation$001--></td>
	      </tr>
      

<tr>

      
        <td colspan="5">
 <h4>ERR05-J. Do not let checked exceptions escape from a finally block</h4>
     <p>Methods invoked from within a finally block can throw an exception. Failure to catch and handle such exceptions results in the abrupt termination of the entire try block. Abrupt termination causes any exception thrown in the try block to be lost, preventing any possible recovery method from handling that specific problem. </p>
        
        <p>In the given program line number <span style="color: red">583 </span> A method invocation <span style="color: red">c.close() </span> is present inside a finally block without a try-catch block </p> 
        <span style="color: #660000">  <h4>Non-compliant Solution</h4></span>
<p> This noncompliant code example contains a finally block that closes the reader object. The programmer incorrectly assumes that the statements in the finally block cannot throw exceptions and consequently fails to appropriately handle any exception that may arise. </p>
 <pre><code class="language-java"> 
 try {
      BufferedReader reader =
          new BufferedReader(new FileReader(some_file));
      try {
        // Do operations
      } finally {
        reader.close();
        // ... Other cleanup code ...
      }
    } catch (IOException x) {
      // Forward to handler
    }
 </code></pre>
<span style="color:#00b33c"><h4>Compliant Solution</h4></span>
<p>  This compliant solution encloses the close() method invocation in a try-catch block of its own within the finally block. Consequently, the potential IOException can be handled without allowing it to propagate further.t</p>
 <pre><code class="language-java"> 
  try {
      BufferedReader reader =
          new BufferedReader(new FileReader(some_file));
      try {
        // Do operations
      } finally {
        try {
          reader.close();
        } catch (IOException ie) {
          // Forward to handler
        }
        // ... Other cleanup code ...
      }
    } catch (IOException x) {
      // Forward to handler
    }
    </code></pre>
<h4>Additional information</h4>
          <ul>
            <li><a href="https://www.securecoding.cert.org/confluence/display/java/ERR05-J.+Do+not+let+checked+exceptions+escape+from+a+finally+block" target="_blank"> ERR05-J. Do not let checked exceptions escape from a finally block</a></li>
          </ul> 
          <h4>Related Guidelines</h4>
          <ul>
            <li><a href="http://cwe.mitre.org/data/definitions/703.html" target="_blank"> CWE-703,</a> Improper Check or Handling of Exceptional Conditions</li>
          <li><a href="http://cwe.mitre.org/data/definitions/248.html" target="_blank"> CWE-248,</a> Uncaught Exception</li>
          
          </ul></td>  </tr>
<!--$newtableblockattachhere-->
    </tbody>
  </table></div>
      </div>
    </div>

    
 
  <div class="panel panel-default">
      <div class="panel-heading">
        <h4 class="panel-title">
          <a data-toggle="collapse" data-parent="#accordion" href="#Loc7">EmailSyncParser.java</a>
        </h4>
      </div>
      <div id="Loc7" class="panel-collapse collapse collapse">
        <div class="panel-body"> <table class="table table-hover table-expandable table-striped">
    <thead>
 <p>Location :<a href="/media/rahul/Education/Project/src/M/Sources/packages/apps/Exchange/src/com/android/exchange/adapter/EmailSyncParser.java">/media/rahul/Education/Project/src/M/Sources/packages/apps/Exchange/src/com/android/exchange/adapter/EmailSyncParser.java</a></p>

      <tr>
        <th>Rule</th>
        <th>Standard</th>
        <th>Line number</th>
        
      </tr>
    </thead>
    <tbody>
      
      
   	  <tr>
		<td>ERR05-J</td>
		<td>CERT</td>
		<td>585</td>
		<td><!--$001violation$001--></td>
	      </tr>
      

<tr>

      
        <td colspan="5">
 <h4>ERR05-J. Do not let checked exceptions escape from a finally block</h4>
     <p>Methods invoked from within a finally block can throw an exception. Failure to catch and handle such exceptions results in the abrupt termination of the entire try block. Abrupt termination causes any exception thrown in the try block to be lost, preventing any possible recovery method from handling that specific problem. </p>
        
        <p>In the given program line number <span style="color: red">585 </span> A method invocation <span style="color: red">c.close() </span> is present inside a finally block without a try-catch block </p> 
        <span style="color: #660000">  <h4>Non-compliant Solution</h4></span>
<p> This noncompliant code example contains a finally block that closes the reader object. The programmer incorrectly assumes that the statements in the finally block cannot throw exceptions and consequently fails to appropriately handle any exception that may arise. </p>
 <pre><code class="language-java"> 
 try {
      BufferedReader reader =
          new BufferedReader(new FileReader(some_file));
      try {
        // Do operations
      } finally {
        reader.close();
        // ... Other cleanup code ...
      }
    } catch (IOException x) {
      // Forward to handler
    }
 </code></pre>
<span style="color:#00b33c"><h4>Compliant Solution</h4></span>
<p>  This compliant solution encloses the close() method invocation in a try-catch block of its own within the finally block. Consequently, the potential IOException can be handled without allowing it to propagate further.t</p>
 <pre><code class="language-java"> 
  try {
      BufferedReader reader =
          new BufferedReader(new FileReader(some_file));
      try {
        // Do operations
      } finally {
        try {
          reader.close();
        } catch (IOException ie) {
          // Forward to handler
        }
        // ... Other cleanup code ...
      }
    } catch (IOException x) {
      // Forward to handler
    }
    </code></pre>
<h4>Additional information</h4>
          <ul>
            <li><a href="https://www.securecoding.cert.org/confluence/display/java/ERR05-J.+Do+not+let+checked+exceptions+escape+from+a+finally+block" target="_blank"> ERR05-J. Do not let checked exceptions escape from a finally block</a></li>
          </ul> 
          <h4>Related Guidelines</h4>
          <ul>
            <li><a href="http://cwe.mitre.org/data/definitions/703.html" target="_blank"> CWE-703,</a> Improper Check or Handling of Exceptional Conditions</li>
          <li><a href="http://cwe.mitre.org/data/definitions/248.html" target="_blank"> CWE-248,</a> Uncaught Exception</li>
          
          </ul></td>  </tr>
	  <tr>
		<td>ERR05-J</td>
		<td>CERT</td>
		<td>631</td>
		<td><!--$001violation$001--></td>
	      </tr>
      

<tr>

      
        <td colspan="5">
 <h4>ERR05-J. Do not let checked exceptions escape from a finally block</h4>
     <p>Methods invoked from within a finally block can throw an exception. Failure to catch and handle such exceptions results in the abrupt termination of the entire try block. Abrupt termination causes any exception thrown in the try block to be lost, preventing any possible recovery method from handling that specific problem. </p>
        
        <p>In the given program line number <span style="color: red">631 </span> A method invocation <span style="color: red">c.close() </span> is present inside a finally block without a try-catch block </p> 
        <span style="color: #660000">  <h4>Non-compliant Solution</h4></span>
<p> This noncompliant code example contains a finally block that closes the reader object. The programmer incorrectly assumes that the statements in the finally block cannot throw exceptions and consequently fails to appropriately handle any exception that may arise. </p>
 <pre><code class="language-java"> 
 try {
      BufferedReader reader =
          new BufferedReader(new FileReader(some_file));
      try {
        // Do operations
      } finally {
        reader.close();
        // ... Other cleanup code ...
      }
    } catch (IOException x) {
      // Forward to handler
    }
 </code></pre>
<span style="color:#00b33c"><h4>Compliant Solution</h4></span>
<p>  This compliant solution encloses the close() method invocation in a try-catch block of its own within the finally block. Consequently, the potential IOException can be handled without allowing it to propagate further.t</p>
 <pre><code class="language-java"> 
  try {
      BufferedReader reader =
          new BufferedReader(new FileReader(some_file));
      try {
        // Do operations
      } finally {
        try {
          reader.close();
        } catch (IOException ie) {
          // Forward to handler
        }
        // ... Other cleanup code ...
      }
    } catch (IOException x) {
      // Forward to handler
    }
    </code></pre>
<h4>Additional information</h4>
          <ul>
            <li><a href="https://www.securecoding.cert.org/confluence/display/java/ERR05-J.+Do+not+let+checked+exceptions+escape+from+a+finally+block" target="_blank"> ERR05-J. Do not let checked exceptions escape from a finally block</a></li>
          </ul> 
          <h4>Related Guidelines</h4>
          <ul>
            <li><a href="http://cwe.mitre.org/data/definitions/703.html" target="_blank"> CWE-703,</a> Improper Check or Handling of Exceptional Conditions</li>
          <li><a href="http://cwe.mitre.org/data/definitions/248.html" target="_blank"> CWE-248,</a> Uncaught Exception</li>
          
          </ul></td>  </tr>
	  <tr>
		<td>ERR05-J</td>
		<td>CERT</td>
		<td>833</td>
		<td><!--$001violation$001--></td>
	      </tr>
      

<tr>

      
        <td colspan="5">
 <h4>ERR05-J. Do not let checked exceptions escape from a finally block</h4>
     <p>Methods invoked from within a finally block can throw an exception. Failure to catch and handle such exceptions results in the abrupt termination of the entire try block. Abrupt termination causes any exception thrown in the try block to be lost, preventing any possible recovery method from handling that specific problem. </p>
        
        <p>In the given program line number <span style="color: red">833 </span> A method invocation <span style="color: red">c.close() </span> is present inside a finally block without a try-catch block </p> 
        <span style="color: #660000">  <h4>Non-compliant Solution</h4></span>
<p> This noncompliant code example contains a finally block that closes the reader object. The programmer incorrectly assumes that the statements in the finally block cannot throw exceptions and consequently fails to appropriately handle any exception that may arise. </p>
 <pre><code class="language-java"> 
 try {
      BufferedReader reader =
          new BufferedReader(new FileReader(some_file));
      try {
        // Do operations
      } finally {
        reader.close();
        // ... Other cleanup code ...
      }
    } catch (IOException x) {
      // Forward to handler
    }
 </code></pre>
<span style="color:#00b33c"><h4>Compliant Solution</h4></span>
<p>  This compliant solution encloses the close() method invocation in a try-catch block of its own within the finally block. Consequently, the potential IOException can be handled without allowing it to propagate further.t</p>
 <pre><code class="language-java"> 
  try {
      BufferedReader reader =
          new BufferedReader(new FileReader(some_file));
      try {
        // Do operations
      } finally {
        try {
          reader.close();
        } catch (IOException ie) {
          // Forward to handler
        }
        // ... Other cleanup code ...
      }
    } catch (IOException x) {
      // Forward to handler
    }
    </code></pre>
<h4>Additional information</h4>
          <ul>
            <li><a href="https://www.securecoding.cert.org/confluence/display/java/ERR05-J.+Do+not+let+checked+exceptions+escape+from+a+finally+block" target="_blank"> ERR05-J. Do not let checked exceptions escape from a finally block</a></li>
          </ul> 
          <h4>Related Guidelines</h4>
          <ul>
            <li><a href="http://cwe.mitre.org/data/definitions/703.html" target="_blank"> CWE-703,</a> Improper Check or Handling of Exceptional Conditions</li>
          <li><a href="http://cwe.mitre.org/data/definitions/248.html" target="_blank"> CWE-248,</a> Uncaught Exception</li>
          
          </ul></td>  </tr>
<!--$newtableblockattachhere-->
    </tbody>
  </table></div>
      </div>
    </div>

    
 
  <div class="panel panel-default">
      <div class="panel-heading">
        <h4 class="panel-title">
          <a data-toggle="collapse" data-parent="#accordion" href="#Loc8">FolderSyncParser.java</a>
        </h4>
      </div>
      <div id="Loc8" class="panel-collapse collapse collapse">
        <div class="panel-body"> <table class="table table-hover table-expandable table-striped">
    <thead>
 <p>Location :<a href="/media/rahul/Education/Project/src/M/Sources/packages/apps/Exchange/src/com/android/exchange/adapter/FolderSyncParser.java">/media/rahul/Education/Project/src/M/Sources/packages/apps/Exchange/src/com/android/exchange/adapter/FolderSyncParser.java</a></p>

      <tr>
        <th>Rule</th>
        <th>Standard</th>
        <th>Line number</th>
        
      </tr>
    </thead>
    <tbody>
      
      
   	  <tr>
		<td>ERR05-J</td>
		<td>CERT</td>
		<td>308</td>
		<td><!--$001violation$001--></td>
	      </tr>
      

<tr>

      
        <td colspan="5">
 <h4>ERR05-J. Do not let checked exceptions escape from a finally block</h4>
     <p>Methods invoked from within a finally block can throw an exception. Failure to catch and handle such exceptions results in the abrupt termination of the entire try block. Abrupt termination causes any exception thrown in the try block to be lost, preventing any possible recovery method from handling that specific problem. </p>
        
        <p>In the given program line number <span style="color: red">308 </span> A method invocation <span style="color: red">c.close() </span> is present inside a finally block without a try-catch block </p> 
        <span style="color: #660000">  <h4>Non-compliant Solution</h4></span>
<p> This noncompliant code example contains a finally block that closes the reader object. The programmer incorrectly assumes that the statements in the finally block cannot throw exceptions and consequently fails to appropriately handle any exception that may arise. </p>
 <pre><code class="language-java"> 
 try {
      BufferedReader reader =
          new BufferedReader(new FileReader(some_file));
      try {
        // Do operations
      } finally {
        reader.close();
        // ... Other cleanup code ...
      }
    } catch (IOException x) {
      // Forward to handler
    }
 </code></pre>
<span style="color:#00b33c"><h4>Compliant Solution</h4></span>
<p>  This compliant solution encloses the close() method invocation in a try-catch block of its own within the finally block. Consequently, the potential IOException can be handled without allowing it to propagate further.t</p>
 <pre><code class="language-java"> 
  try {
      BufferedReader reader =
          new BufferedReader(new FileReader(some_file));
      try {
        // Do operations
      } finally {
        try {
          reader.close();
        } catch (IOException ie) {
          // Forward to handler
        }
        // ... Other cleanup code ...
      }
    } catch (IOException x) {
      // Forward to handler
    }
    </code></pre>
<h4>Additional information</h4>
          <ul>
            <li><a href="https://www.securecoding.cert.org/confluence/display/java/ERR05-J.+Do+not+let+checked+exceptions+escape+from+a+finally+block" target="_blank"> ERR05-J. Do not let checked exceptions escape from a finally block</a></li>
          </ul> 
          <h4>Related Guidelines</h4>
          <ul>
            <li><a href="http://cwe.mitre.org/data/definitions/703.html" target="_blank"> CWE-703,</a> Improper Check or Handling of Exceptional Conditions</li>
          <li><a href="http://cwe.mitre.org/data/definitions/248.html" target="_blank"> CWE-248,</a> Uncaught Exception</li>
          
          </ul></td>  </tr>
	  <tr>
		<td>ERR05-J</td>
		<td>CERT</td>
		<td>370</td>
		<td><!--$001violation$001--></td>
	      </tr>
      

<tr>

      
        <td colspan="5">
 <h4>ERR05-J. Do not let checked exceptions escape from a finally block</h4>
     <p>Methods invoked from within a finally block can throw an exception. Failure to catch and handle such exceptions results in the abrupt termination of the entire try block. Abrupt termination causes any exception thrown in the try block to be lost, preventing any possible recovery method from handling that specific problem. </p>
        
        <p>In the given program line number <span style="color: red">370 </span> A method invocation <span style="color: red">c.close() </span> is present inside a finally block without a try-catch block </p> 
        <span style="color: #660000">  <h4>Non-compliant Solution</h4></span>
<p> This noncompliant code example contains a finally block that closes the reader object. The programmer incorrectly assumes that the statements in the finally block cannot throw exceptions and consequently fails to appropriately handle any exception that may arise. </p>
 <pre><code class="language-java"> 
 try {
      BufferedReader reader =
          new BufferedReader(new FileReader(some_file));
      try {
        // Do operations
      } finally {
        reader.close();
        // ... Other cleanup code ...
      }
    } catch (IOException x) {
      // Forward to handler
    }
 </code></pre>
<span style="color:#00b33c"><h4>Compliant Solution</h4></span>
<p>  This compliant solution encloses the close() method invocation in a try-catch block of its own within the finally block. Consequently, the potential IOException can be handled without allowing it to propagate further.t</p>
 <pre><code class="language-java"> 
  try {
      BufferedReader reader =
          new BufferedReader(new FileReader(some_file));
      try {
        // Do operations
      } finally {
        try {
          reader.close();
        } catch (IOException ie) {
          // Forward to handler
        }
        // ... Other cleanup code ...
      }
    } catch (IOException x) {
      // Forward to handler
    }
    </code></pre>
<h4>Additional information</h4>
          <ul>
            <li><a href="https://www.securecoding.cert.org/confluence/display/java/ERR05-J.+Do+not+let+checked+exceptions+escape+from+a+finally+block" target="_blank"> ERR05-J. Do not let checked exceptions escape from a finally block</a></li>
          </ul> 
          <h4>Related Guidelines</h4>
          <ul>
            <li><a href="http://cwe.mitre.org/data/definitions/703.html" target="_blank"> CWE-703,</a> Improper Check or Handling of Exceptional Conditions</li>
          <li><a href="http://cwe.mitre.org/data/definitions/248.html" target="_blank"> CWE-248,</a> Uncaught Exception</li>
          
          </ul></td>  </tr>
	  <tr>
		<td>ERR05-J</td>
		<td>CERT</td>
		<td>393</td>
		<td><!--$001violation$001--></td>
	      </tr>
      

<tr>

      
        <td colspan="5">
 <h4>ERR05-J. Do not let checked exceptions escape from a finally block</h4>
     <p>Methods invoked from within a finally block can throw an exception. Failure to catch and handle such exceptions results in the abrupt termination of the entire try block. Abrupt termination causes any exception thrown in the try block to be lost, preventing any possible recovery method from handling that specific problem. </p>
        
        <p>In the given program line number <span style="color: red">393 </span> A method invocation <span style="color: red">mSyncOptionsMap.clear() </span> is present inside a finally block without a try-catch block </p> 
        <span style="color: #660000">  <h4>Non-compliant Solution</h4></span>
<p> This noncompliant code example contains a finally block that closes the reader object. The programmer incorrectly assumes that the statements in the finally block cannot throw exceptions and consequently fails to appropriately handle any exception that may arise. </p>
 <pre><code class="language-java"> 
 try {
      BufferedReader reader =
          new BufferedReader(new FileReader(some_file));
      try {
        // Do operations
      } finally {
        reader.close();
        // ... Other cleanup code ...
      }
    } catch (IOException x) {
      // Forward to handler
    }
 </code></pre>
<span style="color:#00b33c"><h4>Compliant Solution</h4></span>
<p>  This compliant solution encloses the close() method invocation in a try-catch block of its own within the finally block. Consequently, the potential IOException can be handled without allowing it to propagate further.t</p>
 <pre><code class="language-java"> 
  try {
      BufferedReader reader =
          new BufferedReader(new FileReader(some_file));
      try {
        // Do operations
      } finally {
        try {
          reader.close();
        } catch (IOException ie) {
          // Forward to handler
        }
        // ... Other cleanup code ...
      }
    } catch (IOException x) {
      // Forward to handler
    }
    </code></pre>
<h4>Additional information</h4>
          <ul>
            <li><a href="https://www.securecoding.cert.org/confluence/display/java/ERR05-J.+Do+not+let+checked+exceptions+escape+from+a+finally+block" target="_blank"> ERR05-J. Do not let checked exceptions escape from a finally block</a></li>
          </ul> 
          <h4>Related Guidelines</h4>
          <ul>
            <li><a href="http://cwe.mitre.org/data/definitions/703.html" target="_blank"> CWE-703,</a> Improper Check or Handling of Exceptional Conditions</li>
          <li><a href="http://cwe.mitre.org/data/definitions/248.html" target="_blank"> CWE-248,</a> Uncaught Exception</li>
          
          </ul></td>  </tr>
	  <tr>
		<td>ERR05-J</td>
		<td>CERT</td>
		<td>559</td>
		<td><!--$001violation$001--></td>
	      </tr>
      

<tr>

      
        <td colspan="5">
 <h4>ERR05-J. Do not let checked exceptions escape from a finally block</h4>
     <p>Methods invoked from within a finally block can throw an exception. Failure to catch and handle such exceptions results in the abrupt termination of the entire try block. Abrupt termination causes any exception thrown in the try block to be lost, preventing any possible recovery method from handling that specific problem. </p>
        
        <p>In the given program line number <span style="color: red">559 </span> A method invocation <span style="color: red">c.close() </span> is present inside a finally block without a try-catch block </p> 
        <span style="color: #660000">  <h4>Non-compliant Solution</h4></span>
<p> This noncompliant code example contains a finally block that closes the reader object. The programmer incorrectly assumes that the statements in the finally block cannot throw exceptions and consequently fails to appropriately handle any exception that may arise. </p>
 <pre><code class="language-java"> 
 try {
      BufferedReader reader =
          new BufferedReader(new FileReader(some_file));
      try {
        // Do operations
      } finally {
        reader.close();
        // ... Other cleanup code ...
      }
    } catch (IOException x) {
      // Forward to handler
    }
 </code></pre>
<span style="color:#00b33c"><h4>Compliant Solution</h4></span>
<p>  This compliant solution encloses the close() method invocation in a try-catch block of its own within the finally block. Consequently, the potential IOException can be handled without allowing it to propagate further.t</p>
 <pre><code class="language-java"> 
  try {
      BufferedReader reader =
          new BufferedReader(new FileReader(some_file));
      try {
        // Do operations
      } finally {
        try {
          reader.close();
        } catch (IOException ie) {
          // Forward to handler
        }
        // ... Other cleanup code ...
      }
    } catch (IOException x) {
      // Forward to handler
    }
    </code></pre>
<h4>Additional information</h4>
          <ul>
            <li><a href="https://www.securecoding.cert.org/confluence/display/java/ERR05-J.+Do+not+let+checked+exceptions+escape+from+a+finally+block" target="_blank"> ERR05-J. Do not let checked exceptions escape from a finally block</a></li>
          </ul> 
          <h4>Related Guidelines</h4>
          <ul>
            <li><a href="http://cwe.mitre.org/data/definitions/703.html" target="_blank"> CWE-703,</a> Improper Check or Handling of Exceptional Conditions</li>
          <li><a href="http://cwe.mitre.org/data/definitions/248.html" target="_blank"> CWE-248,</a> Uncaught Exception</li>
          
          </ul></td>  </tr>
	  <tr>
		<td>ERR05-J</td>
		<td>CERT</td>
		<td>674</td>
		<td><!--$001violation$001--></td>
	      </tr>
      

<tr>

      
        <td colspan="5">
 <h4>ERR05-J. Do not let checked exceptions escape from a finally block</h4>
     <p>Methods invoked from within a finally block can throw an exception. Failure to catch and handle such exceptions results in the abrupt termination of the entire try block. Abrupt termination causes any exception thrown in the try block to be lost, preventing any possible recovery method from handling that specific problem. </p>
        
        <p>In the given program line number <span style="color: red">674 </span> A method invocation <span style="color: red">parentCursor.close() </span> is present inside a finally block without a try-catch block </p> 
        <span style="color: #660000">  <h4>Non-compliant Solution</h4></span>
<p> This noncompliant code example contains a finally block that closes the reader object. The programmer incorrectly assumes that the statements in the finally block cannot throw exceptions and consequently fails to appropriately handle any exception that may arise. </p>
 <pre><code class="language-java"> 
 try {
      BufferedReader reader =
          new BufferedReader(new FileReader(some_file));
      try {
        // Do operations
      } finally {
        reader.close();
        // ... Other cleanup code ...
      }
    } catch (IOException x) {
      // Forward to handler
    }
 </code></pre>
<span style="color:#00b33c"><h4>Compliant Solution</h4></span>
<p>  This compliant solution encloses the close() method invocation in a try-catch block of its own within the finally block. Consequently, the potential IOException can be handled without allowing it to propagate further.t</p>
 <pre><code class="language-java"> 
  try {
      BufferedReader reader =
          new BufferedReader(new FileReader(some_file));
      try {
        // Do operations
      } finally {
        try {
          reader.close();
        } catch (IOException ie) {
          // Forward to handler
        }
        // ... Other cleanup code ...
      }
    } catch (IOException x) {
      // Forward to handler
    }
    </code></pre>
<h4>Additional information</h4>
          <ul>
            <li><a href="https://www.securecoding.cert.org/confluence/display/java/ERR05-J.+Do+not+let+checked+exceptions+escape+from+a+finally+block" target="_blank"> ERR05-J. Do not let checked exceptions escape from a finally block</a></li>
          </ul> 
          <h4>Related Guidelines</h4>
          <ul>
            <li><a href="http://cwe.mitre.org/data/definitions/703.html" target="_blank"> CWE-703,</a> Improper Check or Handling of Exceptional Conditions</li>
          <li><a href="http://cwe.mitre.org/data/definitions/248.html" target="_blank"> CWE-248,</a> Uncaught Exception</li>
          
          </ul></td>  </tr>
	  <tr>
		<td>ERR05-J</td>
		<td>CERT</td>
		<td>696</td>
		<td><!--$001violation$001--></td>
	      </tr>
      

<tr>

      
        <td colspan="5">
 <h4>ERR05-J. Do not let checked exceptions escape from a finally block</h4>
     <p>Methods invoked from within a finally block can throw an exception. Failure to catch and handle such exceptions results in the abrupt termination of the entire try block. Abrupt termination causes any exception thrown in the try block to be lost, preventing any possible recovery method from handling that specific problem. </p>
        
        <p>In the given program line number <span style="color: red">696 </span> A method invocation <span style="color: red">childCursor.close() </span> is present inside a finally block without a try-catch block </p> 
        <span style="color: #660000">  <h4>Non-compliant Solution</h4></span>
<p> This noncompliant code example contains a finally block that closes the reader object. The programmer incorrectly assumes that the statements in the finally block cannot throw exceptions and consequently fails to appropriately handle any exception that may arise. </p>
 <pre><code class="language-java"> 
 try {
      BufferedReader reader =
          new BufferedReader(new FileReader(some_file));
      try {
        // Do operations
      } finally {
        reader.close();
        // ... Other cleanup code ...
      }
    } catch (IOException x) {
      // Forward to handler
    }
 </code></pre>
<span style="color:#00b33c"><h4>Compliant Solution</h4></span>
<p>  This compliant solution encloses the close() method invocation in a try-catch block of its own within the finally block. Consequently, the potential IOException can be handled without allowing it to propagate further.t</p>
 <pre><code class="language-java"> 
  try {
      BufferedReader reader =
          new BufferedReader(new FileReader(some_file));
      try {
        // Do operations
      } finally {
        try {
          reader.close();
        } catch (IOException ie) {
          // Forward to handler
        }
        // ... Other cleanup code ...
      }
    } catch (IOException x) {
      // Forward to handler
    }
    </code></pre>
<h4>Additional information</h4>
          <ul>
            <li><a href="https://www.securecoding.cert.org/confluence/display/java/ERR05-J.+Do+not+let+checked+exceptions+escape+from+a+finally+block" target="_blank"> ERR05-J. Do not let checked exceptions escape from a finally block</a></li>
          </ul> 
          <h4>Related Guidelines</h4>
          <ul>
            <li><a href="http://cwe.mitre.org/data/definitions/703.html" target="_blank"> CWE-703,</a> Improper Check or Handling of Exceptional Conditions</li>
          <li><a href="http://cwe.mitre.org/data/definitions/248.html" target="_blank"> CWE-248,</a> Uncaught Exception</li>
          
          </ul></td>  </tr>
	  <tr>
		<td>ERR05-J</td>
		<td>CERT</td>
		<td>763</td>
		<td><!--$001violation$001--></td>
	      </tr>
      

<tr>

      
        <td colspan="5">
 <h4>ERR05-J. Do not let checked exceptions escape from a finally block</h4>
     <p>Methods invoked from within a finally block can throw an exception. Failure to catch and handle such exceptions results in the abrupt termination of the entire try block. Abrupt termination causes any exception thrown in the try block to be lost, preventing any possible recovery method from handling that specific problem. </p>
        
        <p>In the given program line number <span style="color: red">763 </span> A method invocation <span style="color: red">c.close() </span> is present inside a finally block without a try-catch block </p> 
        <span style="color: #660000">  <h4>Non-compliant Solution</h4></span>
<p> This noncompliant code example contains a finally block that closes the reader object. The programmer incorrectly assumes that the statements in the finally block cannot throw exceptions and consequently fails to appropriately handle any exception that may arise. </p>
 <pre><code class="language-java"> 
 try {
      BufferedReader reader =
          new BufferedReader(new FileReader(some_file));
      try {
        // Do operations
      } finally {
        reader.close();
        // ... Other cleanup code ...
      }
    } catch (IOException x) {
      // Forward to handler
    }
 </code></pre>
<span style="color:#00b33c"><h4>Compliant Solution</h4></span>
<p>  This compliant solution encloses the close() method invocation in a try-catch block of its own within the finally block. Consequently, the potential IOException can be handled without allowing it to propagate further.t</p>
 <pre><code class="language-java"> 
  try {
      BufferedReader reader =
          new BufferedReader(new FileReader(some_file));
      try {
        // Do operations
      } finally {
        try {
          reader.close();
        } catch (IOException ie) {
          // Forward to handler
        }
        // ... Other cleanup code ...
      }
    } catch (IOException x) {
      // Forward to handler
    }
    </code></pre>
<h4>Additional information</h4>
          <ul>
            <li><a href="https://www.securecoding.cert.org/confluence/display/java/ERR05-J.+Do+not+let+checked+exceptions+escape+from+a+finally+block" target="_blank"> ERR05-J. Do not let checked exceptions escape from a finally block</a></li>
          </ul> 
          <h4>Related Guidelines</h4>
          <ul>
            <li><a href="http://cwe.mitre.org/data/definitions/703.html" target="_blank"> CWE-703,</a> Improper Check or Handling of Exceptional Conditions</li>
          <li><a href="http://cwe.mitre.org/data/definitions/248.html" target="_blank"> CWE-248,</a> Uncaught Exception</li>
          
          </ul></td>  </tr>
<!--$newtableblockattachhere-->
    </tbody>
  </table></div>
      </div>
    </div>

    
 
  <div class="panel panel-default">
      <div class="panel-heading">
        <h4 class="panel-title">
          <a data-toggle="collapse" data-parent="#accordion" href="#Loc22">EasSearch.java</a>
        </h4>
      </div>
      <div id="Loc22" class="panel-collapse collapse collapse">
        <div class="panel-body"> <table class="table table-hover table-expandable table-striped">
    <thead>
 <p>Location :<a href="/media/rahul/Education/Project/src/M/Sources/packages/apps/Exchange/src/com/android/exchange/eas/EasSearch.java">/media/rahul/Education/Project/src/M/Sources/packages/apps/Exchange/src/com/android/exchange/eas/EasSearch.java</a></p>

      <tr>
        <th>Rule</th>
        <th>Standard</th>
        <th>Line number</th>
        
      </tr>
    </thead>
    <tbody>
      
      
   	  <tr>
		<td>ERR05-J</td>
		<td>CERT</td>
		<td>157</td>
		<td><!--$001violation$001--></td>
	      </tr>
      

<tr>

      
        <td colspan="5">
 <h4>ERR05-J. Do not let checked exceptions escape from a finally block</h4>
     <p>Methods invoked from within a finally block can throw an exception. Failure to catch and handle such exceptions results in the abrupt termination of the entire try block. Abrupt termination causes any exception thrown in the try block to be lost, preventing any possible recovery method from handling that specific problem. </p>
        
        <p>In the given program line number <span style="color: red">157 </span> A method invocation <span style="color: red">is.close() </span> is present inside a finally block without a try-catch block </p> 
        <span style="color: #660000">  <h4>Non-compliant Solution</h4></span>
<p> This noncompliant code example contains a finally block that closes the reader object. The programmer incorrectly assumes that the statements in the finally block cannot throw exceptions and consequently fails to appropriately handle any exception that may arise. </p>
 <pre><code class="language-java"> 
 try {
      BufferedReader reader =
          new BufferedReader(new FileReader(some_file));
      try {
        // Do operations
      } finally {
        reader.close();
        // ... Other cleanup code ...
      }
    } catch (IOException x) {
      // Forward to handler
    }
 </code></pre>
<span style="color:#00b33c"><h4>Compliant Solution</h4></span>
<p>  This compliant solution encloses the close() method invocation in a try-catch block of its own within the finally block. Consequently, the potential IOException can be handled without allowing it to propagate further.t</p>
 <pre><code class="language-java"> 
  try {
      BufferedReader reader =
          new BufferedReader(new FileReader(some_file));
      try {
        // Do operations
      } finally {
        try {
          reader.close();
        } catch (IOException ie) {
          // Forward to handler
        }
        // ... Other cleanup code ...
      }
    } catch (IOException x) {
      // Forward to handler
    }
    </code></pre>
<h4>Additional information</h4>
          <ul>
            <li><a href="https://www.securecoding.cert.org/confluence/display/java/ERR05-J.+Do+not+let+checked+exceptions+escape+from+a+finally+block" target="_blank"> ERR05-J. Do not let checked exceptions escape from a finally block</a></li>
          </ul> 
          <h4>Related Guidelines</h4>
          <ul>
            <li><a href="http://cwe.mitre.org/data/definitions/703.html" target="_blank"> CWE-703,</a> Improper Check or Handling of Exceptional Conditions</li>
          <li><a href="http://cwe.mitre.org/data/definitions/248.html" target="_blank"> CWE-248,</a> Uncaught Exception</li>
          
          </ul></td>  </tr>
<!--$newtableblockattachhere-->
    </tbody>
  </table></div>
      </div>
    </div>

    
 
  <div class="panel panel-default">
      <div class="panel-heading">
        <h4 class="panel-title">
          <a data-toggle="collapse" data-parent="#accordion" href="#Loc26">EasFullSyncOperation.java</a>
        </h4>
      </div>
      <div id="Loc26" class="panel-collapse collapse collapse">
        <div class="panel-body"> <table class="table table-hover table-expandable table-striped">
    <thead>
 <p>Location :<a href="/media/rahul/Education/Project/src/M/Sources/packages/apps/Exchange/src/com/android/exchange/eas/EasFullSyncOperation.java">/media/rahul/Education/Project/src/M/Sources/packages/apps/Exchange/src/com/android/exchange/eas/EasFullSyncOperation.java</a></p>

      <tr>
        <th>Rule</th>
        <th>Standard</th>
        <th>Line number</th>
        
      </tr>
    </thead>
    <tbody>
      
      
   	  <tr>
		<td>ERR05-J</td>
		<td>CERT</td>
		<td>204</td>
		<td><!--$001violation$001--></td>
	      </tr>
      

<tr>

      
        <td colspan="5">
 <h4>ERR05-J. Do not let checked exceptions escape from a finally block</h4>
     <p>Methods invoked from within a finally block can throw an exception. Failure to catch and handle such exceptions results in the abrupt termination of the entire try block. Abrupt termination causes any exception thrown in the try block to be lost, preventing any possible recovery method from handling that specific problem. </p>
        
        <p>In the given program line number <span style="color: red">204 </span> A method invocation <span style="color: red">c.close() </span> is present inside a finally block without a try-catch block </p> 
        <span style="color: #660000">  <h4>Non-compliant Solution</h4></span>
<p> This noncompliant code example contains a finally block that closes the reader object. The programmer incorrectly assumes that the statements in the finally block cannot throw exceptions and consequently fails to appropriately handle any exception that may arise. </p>
 <pre><code class="language-java"> 
 try {
      BufferedReader reader =
          new BufferedReader(new FileReader(some_file));
      try {
        // Do operations
      } finally {
        reader.close();
        // ... Other cleanup code ...
      }
    } catch (IOException x) {
      // Forward to handler
    }
 </code></pre>
<span style="color:#00b33c"><h4>Compliant Solution</h4></span>
<p>  This compliant solution encloses the close() method invocation in a try-catch block of its own within the finally block. Consequently, the potential IOException can be handled without allowing it to propagate further.t</p>
 <pre><code class="language-java"> 
  try {
      BufferedReader reader =
          new BufferedReader(new FileReader(some_file));
      try {
        // Do operations
      } finally {
        try {
          reader.close();
        } catch (IOException ie) {
          // Forward to handler
        }
        // ... Other cleanup code ...
      }
    } catch (IOException x) {
      // Forward to handler
    }
    </code></pre>
<h4>Additional information</h4>
          <ul>
            <li><a href="https://www.securecoding.cert.org/confluence/display/java/ERR05-J.+Do+not+let+checked+exceptions+escape+from+a+finally+block" target="_blank"> ERR05-J. Do not let checked exceptions escape from a finally block</a></li>
          </ul> 
          <h4>Related Guidelines</h4>
          <ul>
            <li><a href="http://cwe.mitre.org/data/definitions/703.html" target="_blank"> CWE-703,</a> Improper Check or Handling of Exceptional Conditions</li>
          <li><a href="http://cwe.mitre.org/data/definitions/248.html" target="_blank"> CWE-248,</a> Uncaught Exception</li>
          
          </ul></td>  </tr>
	  <tr>
		<td>ERR05-J</td>
		<td>CERT</td>
		<td>269</td>
		<td><!--$001violation$001--></td>
	      </tr>
      

<tr>

      
        <td colspan="5">
 <h4>ERR05-J. Do not let checked exceptions escape from a finally block</h4>
     <p>Methods invoked from within a finally block can throw an exception. Failure to catch and handle such exceptions results in the abrupt termination of the entire try block. Abrupt termination causes any exception thrown in the try block to be lost, preventing any possible recovery method from handling that specific problem. </p>
        
        <p>In the given program line number <span style="color: red">269 </span> A method invocation <span style="color: red">mContext.getContentResolver() </span> is present inside a finally block without a try-catch block </p> 
        <span style="color: #660000">  <h4>Non-compliant Solution</h4></span>
<p> This noncompliant code example contains a finally block that closes the reader object. The programmer incorrectly assumes that the statements in the finally block cannot throw exceptions and consequently fails to appropriately handle any exception that may arise. </p>
 <pre><code class="language-java"> 
 try {
      BufferedReader reader =
          new BufferedReader(new FileReader(some_file));
      try {
        // Do operations
      } finally {
        reader.close();
        // ... Other cleanup code ...
      }
    } catch (IOException x) {
      // Forward to handler
    }
 </code></pre>
<span style="color:#00b33c"><h4>Compliant Solution</h4></span>
<p>  This compliant solution encloses the close() method invocation in a try-catch block of its own within the finally block. Consequently, the potential IOException can be handled without allowing it to propagate further.t</p>
 <pre><code class="language-java"> 
  try {
      BufferedReader reader =
          new BufferedReader(new FileReader(some_file));
      try {
        // Do operations
      } finally {
        try {
          reader.close();
        } catch (IOException ie) {
          // Forward to handler
        }
        // ... Other cleanup code ...
      }
    } catch (IOException x) {
      // Forward to handler
    }
    </code></pre>
<h4>Additional information</h4>
          <ul>
            <li><a href="https://www.securecoding.cert.org/confluence/display/java/ERR05-J.+Do+not+let+checked+exceptions+escape+from+a+finally+block" target="_blank"> ERR05-J. Do not let checked exceptions escape from a finally block</a></li>
          </ul> 
          <h4>Related Guidelines</h4>
          <ul>
            <li><a href="http://cwe.mitre.org/data/definitions/703.html" target="_blank"> CWE-703,</a> Improper Check or Handling of Exceptional Conditions</li>
          <li><a href="http://cwe.mitre.org/data/definitions/248.html" target="_blank"> CWE-248,</a> Uncaught Exception</li>
          
          </ul></td>  </tr>
	  <tr>
		<td>ERR05-J</td>
		<td>CERT</td>
		<td>331</td>
		<td><!--$001violation$001--></td>
	      </tr>
      

<tr>

      
        <td colspan="5">
 <h4>ERR05-J. Do not let checked exceptions escape from a finally block</h4>
     <p>Methods invoked from within a finally block can throw an exception. Failure to catch and handle such exceptions results in the abrupt termination of the entire try block. Abrupt termination causes any exception thrown in the try block to be lost, preventing any possible recovery method from handling that specific problem. </p>
        
        <p>In the given program line number <span style="color: red">331 </span> A method invocation <span style="color: red">c.close() </span> is present inside a finally block without a try-catch block </p> 
        <span style="color: #660000">  <h4>Non-compliant Solution</h4></span>
<p> This noncompliant code example contains a finally block that closes the reader object. The programmer incorrectly assumes that the statements in the finally block cannot throw exceptions and consequently fails to appropriately handle any exception that may arise. </p>
 <pre><code class="language-java"> 
 try {
      BufferedReader reader =
          new BufferedReader(new FileReader(some_file));
      try {
        // Do operations
      } finally {
        reader.close();
        // ... Other cleanup code ...
      }
    } catch (IOException x) {
      // Forward to handler
    }
 </code></pre>
<span style="color:#00b33c"><h4>Compliant Solution</h4></span>
<p>  This compliant solution encloses the close() method invocation in a try-catch block of its own within the finally block. Consequently, the potential IOException can be handled without allowing it to propagate further.t</p>
 <pre><code class="language-java"> 
  try {
      BufferedReader reader =
          new BufferedReader(new FileReader(some_file));
      try {
        // Do operations
      } finally {
        try {
          reader.close();
        } catch (IOException ie) {
          // Forward to handler
        }
        // ... Other cleanup code ...
      }
    } catch (IOException x) {
      // Forward to handler
    }
    </code></pre>
<h4>Additional information</h4>
          <ul>
            <li><a href="https://www.securecoding.cert.org/confluence/display/java/ERR05-J.+Do+not+let+checked+exceptions+escape+from+a+finally+block" target="_blank"> ERR05-J. Do not let checked exceptions escape from a finally block</a></li>
          </ul> 
          <h4>Related Guidelines</h4>
          <ul>
            <li><a href="http://cwe.mitre.org/data/definitions/703.html" target="_blank"> CWE-703,</a> Improper Check or Handling of Exceptional Conditions</li>
          <li><a href="http://cwe.mitre.org/data/definitions/248.html" target="_blank"> CWE-248,</a> Uncaught Exception</li>
          
          </ul></td>  </tr>
<!--$newtableblockattachhere-->
    </tbody>
  </table></div>
      </div>
    </div>

    
 
  <div class="panel panel-default">
      <div class="panel-heading">
        <h4 class="panel-title">
          <a data-toggle="collapse" data-parent="#accordion" href="#Loc27">EasLoadAttachment.java</a>
        </h4>
      </div>
      <div id="Loc27" class="panel-collapse collapse collapse">
        <div class="panel-body"> <table class="table table-hover table-expandable table-striped">
    <thead>
 <p>Location :<a href="/media/rahul/Education/Project/src/M/Sources/packages/apps/Exchange/src/com/android/exchange/eas/EasLoadAttachment.java">/media/rahul/Education/Project/src/M/Sources/packages/apps/Exchange/src/com/android/exchange/eas/EasLoadAttachment.java</a></p>

      <tr>
        <th>Rule</th>
        <th>Standard</th>
        <th>Line number</th>
        
      </tr>
    </thead>
    <tbody>
      
      
   	  <tr>
		<td>ERR05-J</td>
		<td>CERT</td>
		<td>351</td>
		<td><!--$001violation$001--></td>
	      </tr>
      

<tr>

      
        <td colspan="5">
 <h4>ERR05-J. Do not let checked exceptions escape from a finally block</h4>
     <p>Methods invoked from within a finally block can throw an exception. Failure to catch and handle such exceptions results in the abrupt termination of the entire try block. Abrupt termination causes any exception thrown in the try block to be lost, preventing any possible recovery method from handling that specific problem. </p>
        
        <p>In the given program line number <span style="color: red">351 </span> A method invocation <span style="color: red">tmpFile.delete() </span> is present inside a finally block without a try-catch block </p> 
        <span style="color: #660000">  <h4>Non-compliant Solution</h4></span>
<p> This noncompliant code example contains a finally block that closes the reader object. The programmer incorrectly assumes that the statements in the finally block cannot throw exceptions and consequently fails to appropriately handle any exception that may arise. </p>
 <pre><code class="language-java"> 
 try {
      BufferedReader reader =
          new BufferedReader(new FileReader(some_file));
      try {
        // Do operations
      } finally {
        reader.close();
        // ... Other cleanup code ...
      }
    } catch (IOException x) {
      // Forward to handler
    }
 </code></pre>
<span style="color:#00b33c"><h4>Compliant Solution</h4></span>
<p>  This compliant solution encloses the close() method invocation in a try-catch block of its own within the finally block. Consequently, the potential IOException can be handled without allowing it to propagate further.t</p>
 <pre><code class="language-java"> 
  try {
      BufferedReader reader =
          new BufferedReader(new FileReader(some_file));
      try {
        // Do operations
      } finally {
        try {
          reader.close();
        } catch (IOException ie) {
          // Forward to handler
        }
        // ... Other cleanup code ...
      }
    } catch (IOException x) {
      // Forward to handler
    }
    </code></pre>
<h4>Additional information</h4>
          <ul>
            <li><a href="https://www.securecoding.cert.org/confluence/display/java/ERR05-J.+Do+not+let+checked+exceptions+escape+from+a+finally+block" target="_blank"> ERR05-J. Do not let checked exceptions escape from a finally block</a></li>
          </ul> 
          <h4>Related Guidelines</h4>
          <ul>
            <li><a href="http://cwe.mitre.org/data/definitions/703.html" target="_blank"> CWE-703,</a> Improper Check or Handling of Exceptional Conditions</li>
          <li><a href="http://cwe.mitre.org/data/definitions/248.html" target="_blank"> CWE-248,</a> Uncaught Exception</li>
          
          </ul></td>  </tr>
	  <tr>
		<td>ERR05-J</td>
		<td>CERT</td>
		<td>348</td>
		<td><!--$001violation$001--></td>
	      </tr>
      

<tr>

      
        <td colspan="5">
 <h4>ERR05-J. Do not let checked exceptions escape from a finally block</h4>
     <p>Methods invoked from within a finally block can throw an exception. Failure to catch and handle such exceptions results in the abrupt termination of the entire try block. Abrupt termination causes any exception thrown in the try block to be lost, preventing any possible recovery method from handling that specific problem. </p>
        
        <p>In the given program line number <span style="color: red">348 </span> A method invocation <span style="color: red">close(os) </span> is present inside a finally block without a try-catch block </p> 
        <span style="color: #660000">  <h4>Non-compliant Solution</h4></span>
<p> This noncompliant code example contains a finally block that closes the reader object. The programmer incorrectly assumes that the statements in the finally block cannot throw exceptions and consequently fails to appropriately handle any exception that may arise. </p>
 <pre><code class="language-java"> 
 try {
      BufferedReader reader =
          new BufferedReader(new FileReader(some_file));
      try {
        // Do operations
      } finally {
        reader.close();
        // ... Other cleanup code ...
      }
    } catch (IOException x) {
      // Forward to handler
    }
 </code></pre>
<span style="color:#00b33c"><h4>Compliant Solution</h4></span>
<p>  This compliant solution encloses the close() method invocation in a try-catch block of its own within the finally block. Consequently, the potential IOException can be handled without allowing it to propagate further.t</p>
 <pre><code class="language-java"> 
  try {
      BufferedReader reader =
          new BufferedReader(new FileReader(some_file));
      try {
        // Do operations
      } finally {
        try {
          reader.close();
        } catch (IOException ie) {
          // Forward to handler
        }
        // ... Other cleanup code ...
      }
    } catch (IOException x) {
      // Forward to handler
    }
    </code></pre>
<h4>Additional information</h4>
          <ul>
            <li><a href="https://www.securecoding.cert.org/confluence/display/java/ERR05-J.+Do+not+let+checked+exceptions+escape+from+a+finally+block" target="_blank"> ERR05-J. Do not let checked exceptions escape from a finally block</a></li>
          </ul> 
          <h4>Related Guidelines</h4>
          <ul>
            <li><a href="http://cwe.mitre.org/data/definitions/703.html" target="_blank"> CWE-703,</a> Improper Check or Handling of Exceptional Conditions</li>
          <li><a href="http://cwe.mitre.org/data/definitions/248.html" target="_blank"> CWE-248,</a> Uncaught Exception</li>
          
          </ul></td>  </tr>
	  <tr>
		<td>ERR05-J</td>
		<td>CERT</td>
		<td>345</td>
		<td><!--$001violation$001--></td>
	      </tr>
      

<tr>

      
        <td colspan="5">
 <h4>ERR05-J. Do not let checked exceptions escape from a finally block</h4>
     <p>Methods invoked from within a finally block can throw an exception. Failure to catch and handle such exceptions results in the abrupt termination of the entire try block. Abrupt termination causes any exception thrown in the try block to be lost, preventing any possible recovery method from handling that specific problem. </p>
        
        <p>In the given program line number <span style="color: red">345 </span> A method invocation <span style="color: red">close(is) </span> is present inside a finally block without a try-catch block </p> 
        <span style="color: #660000">  <h4>Non-compliant Solution</h4></span>
<p> This noncompliant code example contains a finally block that closes the reader object. The programmer incorrectly assumes that the statements in the finally block cannot throw exceptions and consequently fails to appropriately handle any exception that may arise. </p>
 <pre><code class="language-java"> 
 try {
      BufferedReader reader =
          new BufferedReader(new FileReader(some_file));
      try {
        // Do operations
      } finally {
        reader.close();
        // ... Other cleanup code ...
      }
    } catch (IOException x) {
      // Forward to handler
    }
 </code></pre>
<span style="color:#00b33c"><h4>Compliant Solution</h4></span>
<p>  This compliant solution encloses the close() method invocation in a try-catch block of its own within the finally block. Consequently, the potential IOException can be handled without allowing it to propagate further.t</p>
 <pre><code class="language-java"> 
  try {
      BufferedReader reader =
          new BufferedReader(new FileReader(some_file));
      try {
        // Do operations
      } finally {
        try {
          reader.close();
        } catch (IOException ie) {
          // Forward to handler
        }
        // ... Other cleanup code ...
      }
    } catch (IOException x) {
      // Forward to handler
    }
    </code></pre>
<h4>Additional information</h4>
          <ul>
            <li><a href="https://www.securecoding.cert.org/confluence/display/java/ERR05-J.+Do+not+let+checked+exceptions+escape+from+a+finally+block" target="_blank"> ERR05-J. Do not let checked exceptions escape from a finally block</a></li>
          </ul> 
          <h4>Related Guidelines</h4>
          <ul>
            <li><a href="http://cwe.mitre.org/data/definitions/703.html" target="_blank"> CWE-703,</a> Improper Check or Handling of Exceptional Conditions</li>
          <li><a href="http://cwe.mitre.org/data/definitions/248.html" target="_blank"> CWE-248,</a> Uncaught Exception</li>
          
          </ul></td>  </tr>
	  <tr>
		<td>FIO02-J</td>
		<td>CERT</td>
		<td>351</td>
		<td><!--$001violation$001--></td>
	      </tr>
      

<tr>

      
        <td colspan="5">
 <h4>FIO02-J. Detect and handle file-related errors</h4>
     <p>Java's file-manipulation methods often indicate failure with a return value instead of throwing an exception. Consequently, programs that ignore the return values from file operations often fail to detect that those operations have failed. Java programs must check the return values of methods that perform file I/O.</p>
        
        <p>In the given program line number <span style="color: red">351 </span> code block <span style="color: red">tmpFile.delete();
 </span> trying to delete file without detect and handle file-related errors </p> 
        <span style="color: #660000">  <h4>Non-compliant Solution</h4></span>
<p> This noncompliant code example attempts to delete a specified file but gives no indication of its success.  </p>
 <pre><code class="language-java"> 
 class FileDelete {
	public static void main(String args[]){
		File file = new File("file");
	file.delete();
}
	}
	
 </code></pre>
<span style="color:#00b33c"><h4>Compliant Solution</h4></span>
<p>  This compliant solution checks the return value of delete()</p>
 <pre><code class="language-java"> class FileDelete {
	public static void main(String args[]){
		File file = new File("file");
if (!file.delete()) {
  System.out.println("Deletion failed");
}
	}</code></pre>
<h4>Additional information</h4>
          <ul>
            <li><a href="https://www.securecoding.cert.org/confluence/display/java/FIO02-J.+Detect+and+handle+file-related+errors" target="_blank"> FIO02-J. Detect and handle file-related errors</a></li>
          </ul> 
          <h4>Related Guidelines</h4>
          <ul>
            <li><a href="https://www.securecoding.cert.org/confluence/display/cplusplus/FIO04-CPP.+Detect+and+handle+input+and+output+errors" target="_blank"> FIO04-CPP. Detect and handle input and output errors</a></li>
          </ul></td>  </tr>
<!--$newtableblockattachhere-->
    </tbody>
  </table></div>
      </div>
    </div>

    
 
  <div class="panel panel-default">
      <div class="panel-heading">
        <h4 class="panel-title">
          <a data-toggle="collapse" data-parent="#accordion" href="#Loc29">EasOperation.java</a>
        </h4>
      </div>
      <div id="Loc29" class="panel-collapse collapse collapse">
        <div class="panel-body"> <table class="table table-hover table-expandable table-striped">
    <thead>
 <p>Location :<a href="/media/rahul/Education/Project/src/M/Sources/packages/apps/Exchange/src/com/android/exchange/eas/EasOperation.java">/media/rahul/Education/Project/src/M/Sources/packages/apps/Exchange/src/com/android/exchange/eas/EasOperation.java</a></p>

      <tr>
        <th>Rule</th>
        <th>Standard</th>
        <th>Line number</th>
        
      </tr>
    </thead>
    <tbody>
      
      
   	  <tr>
		<td>ERR05-J</td>
		<td>CERT</td>
		<td>266</td>
		<td><!--$001violation$001--></td>
	      </tr>
      

<tr>

      
        <td colspan="5">
 <h4>ERR05-J. Do not let checked exceptions escape from a finally block</h4>
     <p>Methods invoked from within a finally block can throw an exception. Failure to catch and handle such exceptions results in the abrupt termination of the entire try block. Abrupt termination causes any exception thrown in the try block to be lost, preventing any possible recovery method from handling that specific problem. </p>
        
        <p>In the given program line number <span style="color: red">266 </span> A method invocation <span style="color: red">onRequestComplete() </span> is present inside a finally block without a try-catch block </p> 
        <span style="color: #660000">  <h4>Non-compliant Solution</h4></span>
<p> This noncompliant code example contains a finally block that closes the reader object. The programmer incorrectly assumes that the statements in the finally block cannot throw exceptions and consequently fails to appropriately handle any exception that may arise. </p>
 <pre><code class="language-java"> 
 try {
      BufferedReader reader =
          new BufferedReader(new FileReader(some_file));
      try {
        // Do operations
      } finally {
        reader.close();
        // ... Other cleanup code ...
      }
    } catch (IOException x) {
      // Forward to handler
    }
 </code></pre>
<span style="color:#00b33c"><h4>Compliant Solution</h4></span>
<p>  This compliant solution encloses the close() method invocation in a try-catch block of its own within the finally block. Consequently, the potential IOException can be handled without allowing it to propagate further.t</p>
 <pre><code class="language-java"> 
  try {
      BufferedReader reader =
          new BufferedReader(new FileReader(some_file));
      try {
        // Do operations
      } finally {
        try {
          reader.close();
        } catch (IOException ie) {
          // Forward to handler
        }
        // ... Other cleanup code ...
      }
    } catch (IOException x) {
      // Forward to handler
    }
    </code></pre>
<h4>Additional information</h4>
          <ul>
            <li><a href="https://www.securecoding.cert.org/confluence/display/java/ERR05-J.+Do+not+let+checked+exceptions+escape+from+a+finally+block" target="_blank"> ERR05-J. Do not let checked exceptions escape from a finally block</a></li>
          </ul> 
          <h4>Related Guidelines</h4>
          <ul>
            <li><a href="http://cwe.mitre.org/data/definitions/703.html" target="_blank"> CWE-703,</a> Improper Check or Handling of Exceptional Conditions</li>
          <li><a href="http://cwe.mitre.org/data/definitions/248.html" target="_blank"> CWE-248,</a> Uncaught Exception</li>
          
          </ul></td>  </tr>
	  <tr>
		<td>ERR05-J</td>
		<td>CERT</td>
		<td>281</td>
		<td><!--$001violation$001--></td>
	      </tr>
      

<tr>

      
        <td colspan="5">
 <h4>ERR05-J. Do not let checked exceptions escape from a finally block</h4>
     <p>Methods invoked from within a finally block can throw an exception. Failure to catch and handle such exceptions results in the abrupt termination of the entire try block. Abrupt termination causes any exception thrown in the try block to be lost, preventing any possible recovery method from handling that specific problem. </p>
        
        <p>In the given program line number <span style="color: red">281 </span> A method invocation <span style="color: red">onRequestMade() </span> is present inside a finally block without a try-catch block </p> 
        <span style="color: #660000">  <h4>Non-compliant Solution</h4></span>
<p> This noncompliant code example contains a finally block that closes the reader object. The programmer incorrectly assumes that the statements in the finally block cannot throw exceptions and consequently fails to appropriately handle any exception that may arise. </p>
 <pre><code class="language-java"> 
 try {
      BufferedReader reader =
          new BufferedReader(new FileReader(some_file));
      try {
        // Do operations
      } finally {
        reader.close();
        // ... Other cleanup code ...
      }
    } catch (IOException x) {
      // Forward to handler
    }
 </code></pre>
<span style="color:#00b33c"><h4>Compliant Solution</h4></span>
<p>  This compliant solution encloses the close() method invocation in a try-catch block of its own within the finally block. Consequently, the potential IOException can be handled without allowing it to propagate further.t</p>
 <pre><code class="language-java"> 
  try {
      BufferedReader reader =
          new BufferedReader(new FileReader(some_file));
      try {
        // Do operations
      } finally {
        try {
          reader.close();
        } catch (IOException ie) {
          // Forward to handler
        }
        // ... Other cleanup code ...
      }
    } catch (IOException x) {
      // Forward to handler
    }
    </code></pre>
<h4>Additional information</h4>
          <ul>
            <li><a href="https://www.securecoding.cert.org/confluence/display/java/ERR05-J.+Do+not+let+checked+exceptions+escape+from+a+finally+block" target="_blank"> ERR05-J. Do not let checked exceptions escape from a finally block</a></li>
          </ul> 
          <h4>Related Guidelines</h4>
          <ul>
            <li><a href="http://cwe.mitre.org/data/definitions/703.html" target="_blank"> CWE-703,</a> Improper Check or Handling of Exceptional Conditions</li>
          <li><a href="http://cwe.mitre.org/data/definitions/248.html" target="_blank"> CWE-248,</a> Uncaught Exception</li>
          
          </ul></td>  </tr>
	  <tr>
		<td>ERR05-J</td>
		<td>CERT</td>
		<td>396</td>
		<td><!--$001violation$001--></td>
	      </tr>
      

<tr>

      
        <td colspan="5">
 <h4>ERR05-J. Do not let checked exceptions escape from a finally block</h4>
     <p>Methods invoked from within a finally block can throw an exception. Failure to catch and handle such exceptions results in the abrupt termination of the entire try block. Abrupt termination causes any exception thrown in the try block to be lost, preventing any possible recovery method from handling that specific problem. </p>
        
        <p>In the given program line number <span style="color: red">396 </span> A method invocation <span style="color: red">response.close() </span> is present inside a finally block without a try-catch block </p> 
        <span style="color: #660000">  <h4>Non-compliant Solution</h4></span>
<p> This noncompliant code example contains a finally block that closes the reader object. The programmer incorrectly assumes that the statements in the finally block cannot throw exceptions and consequently fails to appropriately handle any exception that may arise. </p>
 <pre><code class="language-java"> 
 try {
      BufferedReader reader =
          new BufferedReader(new FileReader(some_file));
      try {
        // Do operations
      } finally {
        reader.close();
        // ... Other cleanup code ...
      }
    } catch (IOException x) {
      // Forward to handler
    }
 </code></pre>
<span style="color:#00b33c"><h4>Compliant Solution</h4></span>
<p>  This compliant solution encloses the close() method invocation in a try-catch block of its own within the finally block. Consequently, the potential IOException can be handled without allowing it to propagate further.t</p>
 <pre><code class="language-java"> 
  try {
      BufferedReader reader =
          new BufferedReader(new FileReader(some_file));
      try {
        // Do operations
      } finally {
        try {
          reader.close();
        } catch (IOException ie) {
          // Forward to handler
        }
        // ... Other cleanup code ...
      }
    } catch (IOException x) {
      // Forward to handler
    }
    </code></pre>
<h4>Additional information</h4>
          <ul>
            <li><a href="https://www.securecoding.cert.org/confluence/display/java/ERR05-J.+Do+not+let+checked+exceptions+escape+from+a+finally+block" target="_blank"> ERR05-J. Do not let checked exceptions escape from a finally block</a></li>
          </ul> 
          <h4>Related Guidelines</h4>
          <ul>
            <li><a href="http://cwe.mitre.org/data/definitions/703.html" target="_blank"> CWE-703,</a> Improper Check or Handling of Exceptional Conditions</li>
          <li><a href="http://cwe.mitre.org/data/definitions/248.html" target="_blank"> CWE-248,</a> Uncaught Exception</li>
          
          </ul></td>  </tr>
<!--$newtableblockattachhere-->
    </tbody>
  </table></div>
      </div>
    </div>

    
 
  <div class="panel panel-default">
      <div class="panel-heading">
        <h4 class="panel-title">
          <a data-toggle="collapse" data-parent="#accordion" href="#Loc32">EasPing.java</a>
        </h4>
      </div>
      <div id="Loc32" class="panel-collapse collapse collapse">
        <div class="panel-body"> <table class="table table-hover table-expandable table-striped">
    <thead>
 <p>Location :<a href="/media/rahul/Education/Project/src/M/Sources/packages/apps/Exchange/src/com/android/exchange/eas/EasPing.java">/media/rahul/Education/Project/src/M/Sources/packages/apps/Exchange/src/com/android/exchange/eas/EasPing.java</a></p>

      <tr>
        <th>Rule</th>
        <th>Standard</th>
        <th>Line number</th>
        
      </tr>
    </thead>
    <tbody>
      
      
   	  <tr>
		<td>ERR05-J</td>
		<td>CERT</td>
		<td>166</td>
		<td><!--$001violation$001--></td>
	      </tr>
      

<tr>

      
        <td colspan="5">
 <h4>ERR05-J. Do not let checked exceptions escape from a finally block</h4>
     <p>Methods invoked from within a finally block can throw an exception. Failure to catch and handle such exceptions results in the abrupt termination of the entire try block. Abrupt termination causes any exception thrown in the try block to be lost, preventing any possible recovery method from handling that specific problem. </p>
        
        <p>In the given program line number <span style="color: red">166 </span> A method invocation <span style="color: red">c.close() </span> is present inside a finally block without a try-catch block </p> 
        <span style="color: #660000">  <h4>Non-compliant Solution</h4></span>
<p> This noncompliant code example contains a finally block that closes the reader object. The programmer incorrectly assumes that the statements in the finally block cannot throw exceptions and consequently fails to appropriately handle any exception that may arise. </p>
 <pre><code class="language-java"> 
 try {
      BufferedReader reader =
          new BufferedReader(new FileReader(some_file));
      try {
        // Do operations
      } finally {
        reader.close();
        // ... Other cleanup code ...
      }
    } catch (IOException x) {
      // Forward to handler
    }
 </code></pre>
<span style="color:#00b33c"><h4>Compliant Solution</h4></span>
<p>  This compliant solution encloses the close() method invocation in a try-catch block of its own within the finally block. Consequently, the potential IOException can be handled without allowing it to propagate further.t</p>
 <pre><code class="language-java"> 
  try {
      BufferedReader reader =
          new BufferedReader(new FileReader(some_file));
      try {
        // Do operations
      } finally {
        try {
          reader.close();
        } catch (IOException ie) {
          // Forward to handler
        }
        // ... Other cleanup code ...
      }
    } catch (IOException x) {
      // Forward to handler
    }
    </code></pre>
<h4>Additional information</h4>
          <ul>
            <li><a href="https://www.securecoding.cert.org/confluence/display/java/ERR05-J.+Do+not+let+checked+exceptions+escape+from+a+finally+block" target="_blank"> ERR05-J. Do not let checked exceptions escape from a finally block</a></li>
          </ul> 
          <h4>Related Guidelines</h4>
          <ul>
            <li><a href="http://cwe.mitre.org/data/definitions/703.html" target="_blank"> CWE-703,</a> Improper Check or Handling of Exceptional Conditions</li>
          <li><a href="http://cwe.mitre.org/data/definitions/248.html" target="_blank"> CWE-248,</a> Uncaught Exception</li>
          
          </ul></td>  </tr>
	  <tr>
		<td>ERR05-J</td>
		<td>CERT</td>
		<td>376</td>
		<td><!--$001violation$001--></td>
	      </tr>
      

<tr>

      
        <td colspan="5">
 <h4>ERR05-J. Do not let checked exceptions escape from a finally block</h4>
     <p>Methods invoked from within a finally block can throw an exception. Failure to catch and handle such exceptions results in the abrupt termination of the entire try block. Abrupt termination causes any exception thrown in the try block to be lost, preventing any possible recovery method from handling that specific problem. </p>
        
        <p>In the given program line number <span style="color: red">376 </span> A method invocation <span style="color: red">c.close() </span> is present inside a finally block without a try-catch block </p> 
        <span style="color: #660000">  <h4>Non-compliant Solution</h4></span>
<p> This noncompliant code example contains a finally block that closes the reader object. The programmer incorrectly assumes that the statements in the finally block cannot throw exceptions and consequently fails to appropriately handle any exception that may arise. </p>
 <pre><code class="language-java"> 
 try {
      BufferedReader reader =
          new BufferedReader(new FileReader(some_file));
      try {
        // Do operations
      } finally {
        reader.close();
        // ... Other cleanup code ...
      }
    } catch (IOException x) {
      // Forward to handler
    }
 </code></pre>
<span style="color:#00b33c"><h4>Compliant Solution</h4></span>
<p>  This compliant solution encloses the close() method invocation in a try-catch block of its own within the finally block. Consequently, the potential IOException can be handled without allowing it to propagate further.t</p>
 <pre><code class="language-java"> 
  try {
      BufferedReader reader =
          new BufferedReader(new FileReader(some_file));
      try {
        // Do operations
      } finally {
        try {
          reader.close();
        } catch (IOException ie) {
          // Forward to handler
        }
        // ... Other cleanup code ...
      }
    } catch (IOException x) {
      // Forward to handler
    }
    </code></pre>
<h4>Additional information</h4>
          <ul>
            <li><a href="https://www.securecoding.cert.org/confluence/display/java/ERR05-J.+Do+not+let+checked+exceptions+escape+from+a+finally+block" target="_blank"> ERR05-J. Do not let checked exceptions escape from a finally block</a></li>
          </ul> 
          <h4>Related Guidelines</h4>
          <ul>
            <li><a href="http://cwe.mitre.org/data/definitions/703.html" target="_blank"> CWE-703,</a> Improper Check or Handling of Exceptional Conditions</li>
          <li><a href="http://cwe.mitre.org/data/definitions/248.html" target="_blank"> CWE-248,</a> Uncaught Exception</li>
          
          </ul></td>  </tr>
<!--$newtableblockattachhere-->
    </tbody>
  </table></div>
      </div>
    </div>

    
 
  <div class="panel panel-default">
      <div class="panel-heading">
        <h4 class="panel-title">
          <a data-toggle="collapse" data-parent="#accordion" href="#Loc34">EasSearchGal.java</a>
        </h4>
      </div>
      <div id="Loc34" class="panel-collapse collapse collapse">
        <div class="panel-body"> <table class="table table-hover table-expandable table-striped">
    <thead>
 <p>Location :<a href="/media/rahul/Education/Project/src/M/Sources/packages/apps/Exchange/src/com/android/exchange/eas/EasSearchGal.java">/media/rahul/Education/Project/src/M/Sources/packages/apps/Exchange/src/com/android/exchange/eas/EasSearchGal.java</a></p>

      <tr>
        <th>Rule</th>
        <th>Standard</th>
        <th>Line number</th>
        
      </tr>
    </thead>
    <tbody>
      
      
   	  <tr>
		<td>ERR05-J</td>
		<td>CERT</td>
		<td>77</td>
		<td><!--$001violation$001--></td>
	      </tr>
      

<tr>

      
        <td colspan="5">
 <h4>ERR05-J. Do not let checked exceptions escape from a finally block</h4>
     <p>Methods invoked from within a finally block can throw an exception. Failure to catch and handle such exceptions results in the abrupt termination of the entire try block. Abrupt termination causes any exception thrown in the try block to be lost, preventing any possible recovery method from handling that specific problem. </p>
        
        <p>In the given program line number <span style="color: red">77 </span> A method invocation <span style="color: red">is.close() </span> is present inside a finally block without a try-catch block </p> 
        <span style="color: #660000">  <h4>Non-compliant Solution</h4></span>
<p> This noncompliant code example contains a finally block that closes the reader object. The programmer incorrectly assumes that the statements in the finally block cannot throw exceptions and consequently fails to appropriately handle any exception that may arise. </p>
 <pre><code class="language-java"> 
 try {
      BufferedReader reader =
          new BufferedReader(new FileReader(some_file));
      try {
        // Do operations
      } finally {
        reader.close();
        // ... Other cleanup code ...
      }
    } catch (IOException x) {
      // Forward to handler
    }
 </code></pre>
<span style="color:#00b33c"><h4>Compliant Solution</h4></span>
<p>  This compliant solution encloses the close() method invocation in a try-catch block of its own within the finally block. Consequently, the potential IOException can be handled without allowing it to propagate further.t</p>
 <pre><code class="language-java"> 
  try {
      BufferedReader reader =
          new BufferedReader(new FileReader(some_file));
      try {
        // Do operations
      } finally {
        try {
          reader.close();
        } catch (IOException ie) {
          // Forward to handler
        }
        // ... Other cleanup code ...
      }
    } catch (IOException x) {
      // Forward to handler
    }
    </code></pre>
<h4>Additional information</h4>
          <ul>
            <li><a href="https://www.securecoding.cert.org/confluence/display/java/ERR05-J.+Do+not+let+checked+exceptions+escape+from+a+finally+block" target="_blank"> ERR05-J. Do not let checked exceptions escape from a finally block</a></li>
          </ul> 
          <h4>Related Guidelines</h4>
          <ul>
            <li><a href="http://cwe.mitre.org/data/definitions/703.html" target="_blank"> CWE-703,</a> Improper Check or Handling of Exceptional Conditions</li>
          <li><a href="http://cwe.mitre.org/data/definitions/248.html" target="_blank"> CWE-248,</a> Uncaught Exception</li>
          
          </ul></td>  </tr>
<!--$newtableblockattachhere-->
    </tbody>
  </table></div>
      </div>
    </div>

    
 
  <div class="panel panel-default">
      <div class="panel-heading">
        <h4 class="panel-title">
          <a data-toggle="collapse" data-parent="#accordion" href="#Loc37">EasSync.java</a>
        </h4>
      </div>
      <div id="Loc37" class="panel-collapse collapse collapse">
        <div class="panel-body"> <table class="table table-hover table-expandable table-striped">
    <thead>
 <p>Location :<a href="/media/rahul/Education/Project/src/M/Sources/packages/apps/Exchange/src/com/android/exchange/eas/EasSync.java">/media/rahul/Education/Project/src/M/Sources/packages/apps/Exchange/src/com/android/exchange/eas/EasSync.java</a></p>

      <tr>
        <th>Rule</th>
        <th>Standard</th>
        <th>Line number</th>
        
      </tr>
    </thead>
    <tbody>
      
      
   	  <tr>
		<td>ERR05-J</td>
		<td>CERT</td>
		<td>174</td>
		<td><!--$001violation$001--></td>
	      </tr>
      

<tr>

      
        <td colspan="5">
 <h4>ERR05-J. Do not let checked exceptions escape from a finally block</h4>
     <p>Methods invoked from within a finally block can throw an exception. Failure to catch and handle such exceptions results in the abrupt termination of the entire try block. Abrupt termination causes any exception thrown in the try block to be lost, preventing any possible recovery method from handling that specific problem. </p>
        
        <p>In the given program line number <span style="color: red">174 </span> A method invocation <span style="color: red">mailboxCursor.close() </span> is present inside a finally block without a try-catch block </p> 
        <span style="color: #660000">  <h4>Non-compliant Solution</h4></span>
<p> This noncompliant code example contains a finally block that closes the reader object. The programmer incorrectly assumes that the statements in the finally block cannot throw exceptions and consequently fails to appropriately handle any exception that may arise. </p>
 <pre><code class="language-java"> 
 try {
      BufferedReader reader =
          new BufferedReader(new FileReader(some_file));
      try {
        // Do operations
      } finally {
        reader.close();
        // ... Other cleanup code ...
      }
    } catch (IOException x) {
      // Forward to handler
    }
 </code></pre>
<span style="color:#00b33c"><h4>Compliant Solution</h4></span>
<p>  This compliant solution encloses the close() method invocation in a try-catch block of its own within the finally block. Consequently, the potential IOException can be handled without allowing it to propagate further.t</p>
 <pre><code class="language-java"> 
  try {
      BufferedReader reader =
          new BufferedReader(new FileReader(some_file));
      try {
        // Do operations
      } finally {
        try {
          reader.close();
        } catch (IOException ie) {
          // Forward to handler
        }
        // ... Other cleanup code ...
      }
    } catch (IOException x) {
      // Forward to handler
    }
    </code></pre>
<h4>Additional information</h4>
          <ul>
            <li><a href="https://www.securecoding.cert.org/confluence/display/java/ERR05-J.+Do+not+let+checked+exceptions+escape+from+a+finally+block" target="_blank"> ERR05-J. Do not let checked exceptions escape from a finally block</a></li>
          </ul> 
          <h4>Related Guidelines</h4>
          <ul>
            <li><a href="http://cwe.mitre.org/data/definitions/703.html" target="_blank"> CWE-703,</a> Improper Check or Handling of Exceptional Conditions</li>
          <li><a href="http://cwe.mitre.org/data/definitions/248.html" target="_blank"> CWE-248,</a> Uncaught Exception</li>
          
          </ul></td>  </tr>
<!--$newtableblockattachhere-->
    </tbody>
  </table></div>
      </div>
    </div>

    
 
  <div class="panel panel-default">
      <div class="panel-heading">
        <h4 class="panel-title">
          <a data-toggle="collapse" data-parent="#accordion" href="#Loc39">EasSyncCalendar.java</a>
        </h4>
      </div>
      <div id="Loc39" class="panel-collapse collapse collapse">
        <div class="panel-body"> <table class="table table-hover table-expandable table-striped">
    <thead>
 <p>Location :<a href="/media/rahul/Education/Project/src/M/Sources/packages/apps/Exchange/src/com/android/exchange/eas/EasSyncCalendar.java">/media/rahul/Education/Project/src/M/Sources/packages/apps/Exchange/src/com/android/exchange/eas/EasSyncCalendar.java</a></p>

      <tr>
        <th>Rule</th>
        <th>Standard</th>
        <th>Line number</th>
        
      </tr>
    </thead>
    <tbody>
      
      
   	  <tr>
		<td>ERR05-J</td>
		<td>CERT</td>
		<td>185</td>
		<td><!--$001violation$001--></td>
	      </tr>
      

<tr>

      
        <td colspan="5">
 <h4>ERR05-J. Do not let checked exceptions escape from a finally block</h4>
     <p>Methods invoked from within a finally block can throw an exception. Failure to catch and handle such exceptions results in the abrupt termination of the entire try block. Abrupt termination causes any exception thrown in the try block to be lost, preventing any possible recovery method from handling that specific problem. </p>
        
        <p>In the given program line number <span style="color: red">185 </span> A method invocation <span style="color: red">c.close() </span> is present inside a finally block without a try-catch block </p> 
        <span style="color: #660000">  <h4>Non-compliant Solution</h4></span>
<p> This noncompliant code example contains a finally block that closes the reader object. The programmer incorrectly assumes that the statements in the finally block cannot throw exceptions and consequently fails to appropriately handle any exception that may arise. </p>
 <pre><code class="language-java"> 
 try {
      BufferedReader reader =
          new BufferedReader(new FileReader(some_file));
      try {
        // Do operations
      } finally {
        reader.close();
        // ... Other cleanup code ...
      }
    } catch (IOException x) {
      // Forward to handler
    }
 </code></pre>
<span style="color:#00b33c"><h4>Compliant Solution</h4></span>
<p>  This compliant solution encloses the close() method invocation in a try-catch block of its own within the finally block. Consequently, the potential IOException can be handled without allowing it to propagate further.t</p>
 <pre><code class="language-java"> 
  try {
      BufferedReader reader =
          new BufferedReader(new FileReader(some_file));
      try {
        // Do operations
      } finally {
        try {
          reader.close();
        } catch (IOException ie) {
          // Forward to handler
        }
        // ... Other cleanup code ...
      }
    } catch (IOException x) {
      // Forward to handler
    }
    </code></pre>
<h4>Additional information</h4>
          <ul>
            <li><a href="https://www.securecoding.cert.org/confluence/display/java/ERR05-J.+Do+not+let+checked+exceptions+escape+from+a+finally+block" target="_blank"> ERR05-J. Do not let checked exceptions escape from a finally block</a></li>
          </ul> 
          <h4>Related Guidelines</h4>
          <ul>
            <li><a href="http://cwe.mitre.org/data/definitions/703.html" target="_blank"> CWE-703,</a> Improper Check or Handling of Exceptional Conditions</li>
          <li><a href="http://cwe.mitre.org/data/definitions/248.html" target="_blank"> CWE-248,</a> Uncaught Exception</li>
          
          </ul></td>  </tr>
	  <tr>
		<td>ERR05-J</td>
		<td>CERT</td>
		<td>173</td>
		<td><!--$001violation$001--></td>
	      </tr>
      

<tr>

      
        <td colspan="5">
 <h4>ERR05-J. Do not let checked exceptions escape from a finally block</h4>
     <p>Methods invoked from within a finally block can throw an exception. Failure to catch and handle such exceptions results in the abrupt termination of the entire try block. Abrupt termination causes any exception thrown in the try block to be lost, preventing any possible recovery method from handling that specific problem. </p>
        
        <p>In the given program line number <span style="color: red">173 </span> A method invocation <span style="color: red">c1.close() </span> is present inside a finally block without a try-catch block </p> 
        <span style="color: #660000">  <h4>Non-compliant Solution</h4></span>
<p> This noncompliant code example contains a finally block that closes the reader object. The programmer incorrectly assumes that the statements in the finally block cannot throw exceptions and consequently fails to appropriately handle any exception that may arise. </p>
 <pre><code class="language-java"> 
 try {
      BufferedReader reader =
          new BufferedReader(new FileReader(some_file));
      try {
        // Do operations
      } finally {
        reader.close();
        // ... Other cleanup code ...
      }
    } catch (IOException x) {
      // Forward to handler
    }
 </code></pre>
<span style="color:#00b33c"><h4>Compliant Solution</h4></span>
<p>  This compliant solution encloses the close() method invocation in a try-catch block of its own within the finally block. Consequently, the potential IOException can be handled without allowing it to propagate further.t</p>
 <pre><code class="language-java"> 
  try {
      BufferedReader reader =
          new BufferedReader(new FileReader(some_file));
      try {
        // Do operations
      } finally {
        try {
          reader.close();
        } catch (IOException ie) {
          // Forward to handler
        }
        // ... Other cleanup code ...
      }
    } catch (IOException x) {
      // Forward to handler
    }
    </code></pre>
<h4>Additional information</h4>
          <ul>
            <li><a href="https://www.securecoding.cert.org/confluence/display/java/ERR05-J.+Do+not+let+checked+exceptions+escape+from+a+finally+block" target="_blank"> ERR05-J. Do not let checked exceptions escape from a finally block</a></li>
          </ul> 
          <h4>Related Guidelines</h4>
          <ul>
            <li><a href="http://cwe.mitre.org/data/definitions/703.html" target="_blank"> CWE-703,</a> Improper Check or Handling of Exceptional Conditions</li>
          <li><a href="http://cwe.mitre.org/data/definitions/248.html" target="_blank"> CWE-248,</a> Uncaught Exception</li>
          
          </ul></td>  </tr>
	  <tr>
		<td>ERR05-J</td>
		<td>CERT</td>
		<td>285</td>
		<td><!--$001violation$001--></td>
	      </tr>
      

<tr>

      
        <td colspan="5">
 <h4>ERR05-J. Do not let checked exceptions escape from a finally block</h4>
     <p>Methods invoked from within a finally block can throw an exception. Failure to catch and handle such exceptions results in the abrupt termination of the entire try block. Abrupt termination causes any exception thrown in the try block to be lost, preventing any possible recovery method from handling that specific problem. </p>
        
        <p>In the given program line number <span style="color: red">285 </span> A method invocation <span style="color: red">c.close() </span> is present inside a finally block without a try-catch block </p> 
        <span style="color: #660000">  <h4>Non-compliant Solution</h4></span>
<p> This noncompliant code example contains a finally block that closes the reader object. The programmer incorrectly assumes that the statements in the finally block cannot throw exceptions and consequently fails to appropriately handle any exception that may arise. </p>
 <pre><code class="language-java"> 
 try {
      BufferedReader reader =
          new BufferedReader(new FileReader(some_file));
      try {
        // Do operations
      } finally {
        reader.close();
        // ... Other cleanup code ...
      }
    } catch (IOException x) {
      // Forward to handler
    }
 </code></pre>
<span style="color:#00b33c"><h4>Compliant Solution</h4></span>
<p>  This compliant solution encloses the close() method invocation in a try-catch block of its own within the finally block. Consequently, the potential IOException can be handled without allowing it to propagate further.t</p>
 <pre><code class="language-java"> 
  try {
      BufferedReader reader =
          new BufferedReader(new FileReader(some_file));
      try {
        // Do operations
      } finally {
        try {
          reader.close();
        } catch (IOException ie) {
          // Forward to handler
        }
        // ... Other cleanup code ...
      }
    } catch (IOException x) {
      // Forward to handler
    }
    </code></pre>
<h4>Additional information</h4>
          <ul>
            <li><a href="https://www.securecoding.cert.org/confluence/display/java/ERR05-J.+Do+not+let+checked+exceptions+escape+from+a+finally+block" target="_blank"> ERR05-J. Do not let checked exceptions escape from a finally block</a></li>
          </ul> 
          <h4>Related Guidelines</h4>
          <ul>
            <li><a href="http://cwe.mitre.org/data/definitions/703.html" target="_blank"> CWE-703,</a> Improper Check or Handling of Exceptional Conditions</li>
          <li><a href="http://cwe.mitre.org/data/definitions/248.html" target="_blank"> CWE-248,</a> Uncaught Exception</li>
          
          </ul></td>  </tr>
	  <tr>
		<td>ERR05-J</td>
		<td>CERT</td>
		<td>1037</td>
		<td><!--$001violation$001--></td>
	      </tr>
      

<tr>

      
        <td colspan="5">
 <h4>ERR05-J. Do not let checked exceptions escape from a finally block</h4>
     <p>Methods invoked from within a finally block can throw an exception. Failure to catch and handle such exceptions results in the abrupt termination of the entire try block. Abrupt termination causes any exception thrown in the try block to be lost, preventing any possible recovery method from handling that specific problem. </p>
        
        <p>In the given program line number <span style="color: red">1037 </span> A method invocation <span style="color: red">eventIterator.close() </span> is present inside a finally block without a try-catch block </p> 
        <span style="color: #660000">  <h4>Non-compliant Solution</h4></span>
<p> This noncompliant code example contains a finally block that closes the reader object. The programmer incorrectly assumes that the statements in the finally block cannot throw exceptions and consequently fails to appropriately handle any exception that may arise. </p>
 <pre><code class="language-java"> 
 try {
      BufferedReader reader =
          new BufferedReader(new FileReader(some_file));
      try {
        // Do operations
      } finally {
        reader.close();
        // ... Other cleanup code ...
      }
    } catch (IOException x) {
      // Forward to handler
    }
 </code></pre>
<span style="color:#00b33c"><h4>Compliant Solution</h4></span>
<p>  This compliant solution encloses the close() method invocation in a try-catch block of its own within the finally block. Consequently, the potential IOException can be handled without allowing it to propagate further.t</p>
 <pre><code class="language-java"> 
  try {
      BufferedReader reader =
          new BufferedReader(new FileReader(some_file));
      try {
        // Do operations
      } finally {
        try {
          reader.close();
        } catch (IOException ie) {
          // Forward to handler
        }
        // ... Other cleanup code ...
      }
    } catch (IOException x) {
      // Forward to handler
    }
    </code></pre>
<h4>Additional information</h4>
          <ul>
            <li><a href="https://www.securecoding.cert.org/confluence/display/java/ERR05-J.+Do+not+let+checked+exceptions+escape+from+a+finally+block" target="_blank"> ERR05-J. Do not let checked exceptions escape from a finally block</a></li>
          </ul> 
          <h4>Related Guidelines</h4>
          <ul>
            <li><a href="http://cwe.mitre.org/data/definitions/703.html" target="_blank"> CWE-703,</a> Improper Check or Handling of Exceptional Conditions</li>
          <li><a href="http://cwe.mitre.org/data/definitions/248.html" target="_blank"> CWE-248,</a> Uncaught Exception</li>
          
          </ul></td>  </tr>
<!--$newtableblockattachhere-->
    </tbody>
  </table></div>
      </div>
    </div>

    
 
  <div class="panel panel-default">
      <div class="panel-heading">
        <h4 class="panel-title">
          <a data-toggle="collapse" data-parent="#accordion" href="#Loc41">EasSyncContacts.java</a>
        </h4>
      </div>
      <div id="Loc41" class="panel-collapse collapse collapse">
        <div class="panel-body"> <table class="table table-hover table-expandable table-striped">
    <thead>
 <p>Location :<a href="/media/rahul/Education/Project/src/M/Sources/packages/apps/Exchange/src/com/android/exchange/eas/EasSyncContacts.java">/media/rahul/Education/Project/src/M/Sources/packages/apps/Exchange/src/com/android/exchange/eas/EasSyncContacts.java</a></p>

      <tr>
        <th>Rule</th>
        <th>Standard</th>
        <th>Line number</th>
        
      </tr>
    </thead>
    <tbody>
      
      
   	  <tr>
		<td>ERR05-J</td>
		<td>CERT</td>
		<td>318</td>
		<td><!--$001violation$001--></td>
	      </tr>
      

<tr>

      
        <td colspan="5">
 <h4>ERR05-J. Do not let checked exceptions escape from a finally block</h4>
     <p>Methods invoked from within a finally block can throw an exception. Failure to catch and handle such exceptions results in the abrupt termination of the entire try block. Abrupt termination causes any exception thrown in the try block to be lost, preventing any possible recovery method from handling that specific problem. </p>
        
        <p>In the given program line number <span style="color: red">318 </span> A method invocation <span style="color: red">c.close() </span> is present inside a finally block without a try-catch block </p> 
        <span style="color: #660000">  <h4>Non-compliant Solution</h4></span>
<p> This noncompliant code example contains a finally block that closes the reader object. The programmer incorrectly assumes that the statements in the finally block cannot throw exceptions and consequently fails to appropriately handle any exception that may arise. </p>
 <pre><code class="language-java"> 
 try {
      BufferedReader reader =
          new BufferedReader(new FileReader(some_file));
      try {
        // Do operations
      } finally {
        reader.close();
        // ... Other cleanup code ...
      }
    } catch (IOException x) {
      // Forward to handler
    }
 </code></pre>
<span style="color:#00b33c"><h4>Compliant Solution</h4></span>
<p>  This compliant solution encloses the close() method invocation in a try-catch block of its own within the finally block. Consequently, the potential IOException can be handled without allowing it to propagate further.t</p>
 <pre><code class="language-java"> 
  try {
      BufferedReader reader =
          new BufferedReader(new FileReader(some_file));
      try {
        // Do operations
      } finally {
        try {
          reader.close();
        } catch (IOException ie) {
          // Forward to handler
        }
        // ... Other cleanup code ...
      }
    } catch (IOException x) {
      // Forward to handler
    }
    </code></pre>
<h4>Additional information</h4>
          <ul>
            <li><a href="https://www.securecoding.cert.org/confluence/display/java/ERR05-J.+Do+not+let+checked+exceptions+escape+from+a+finally+block" target="_blank"> ERR05-J. Do not let checked exceptions escape from a finally block</a></li>
          </ul> 
          <h4>Related Guidelines</h4>
          <ul>
            <li><a href="http://cwe.mitre.org/data/definitions/703.html" target="_blank"> CWE-703,</a> Improper Check or Handling of Exceptional Conditions</li>
          <li><a href="http://cwe.mitre.org/data/definitions/248.html" target="_blank"> CWE-248,</a> Uncaught Exception</li>
          
          </ul></td>  </tr>
	  <tr>
		<td>ERR05-J</td>
		<td>CERT</td>
		<td>1008</td>
		<td><!--$001violation$001--></td>
	      </tr>
      

<tr>

      
        <td colspan="5">
 <h4>ERR05-J. Do not let checked exceptions escape from a finally block</h4>
     <p>Methods invoked from within a finally block can throw an exception. Failure to catch and handle such exceptions results in the abrupt termination of the entire try block. Abrupt termination causes any exception thrown in the try block to be lost, preventing any possible recovery method from handling that specific problem. </p>
        
        <p>In the given program line number <span style="color: red">1008 </span> A method invocation <span style="color: red">ei.close() </span> is present inside a finally block without a try-catch block </p> 
        <span style="color: #660000">  <h4>Non-compliant Solution</h4></span>
<p> This noncompliant code example contains a finally block that closes the reader object. The programmer incorrectly assumes that the statements in the finally block cannot throw exceptions and consequently fails to appropriately handle any exception that may arise. </p>
 <pre><code class="language-java"> 
 try {
      BufferedReader reader =
          new BufferedReader(new FileReader(some_file));
      try {
        // Do operations
      } finally {
        reader.close();
        // ... Other cleanup code ...
      }
    } catch (IOException x) {
      // Forward to handler
    }
 </code></pre>
<span style="color:#00b33c"><h4>Compliant Solution</h4></span>
<p>  This compliant solution encloses the close() method invocation in a try-catch block of its own within the finally block. Consequently, the potential IOException can be handled without allowing it to propagate further.t</p>
 <pre><code class="language-java"> 
  try {
      BufferedReader reader =
          new BufferedReader(new FileReader(some_file));
      try {
        // Do operations
      } finally {
        try {
          reader.close();
        } catch (IOException ie) {
          // Forward to handler
        }
        // ... Other cleanup code ...
      }
    } catch (IOException x) {
      // Forward to handler
    }
    </code></pre>
<h4>Additional information</h4>
          <ul>
            <li><a href="https://www.securecoding.cert.org/confluence/display/java/ERR05-J.+Do+not+let+checked+exceptions+escape+from+a+finally+block" target="_blank"> ERR05-J. Do not let checked exceptions escape from a finally block</a></li>
          </ul> 
          <h4>Related Guidelines</h4>
          <ul>
            <li><a href="http://cwe.mitre.org/data/definitions/703.html" target="_blank"> CWE-703,</a> Improper Check or Handling of Exceptional Conditions</li>
          <li><a href="http://cwe.mitre.org/data/definitions/248.html" target="_blank"> CWE-248,</a> Uncaught Exception</li>
          
          </ul></td>  </tr>
	  <tr>
		<td>ERR05-J</td>
		<td>CERT</td>
		<td>967</td>
		<td><!--$001violation$001--></td>
	      </tr>
      

<tr>

      
        <td colspan="5">
 <h4>ERR05-J. Do not let checked exceptions escape from a finally block</h4>
     <p>Methods invoked from within a finally block can throw an exception. Failure to catch and handle such exceptions results in the abrupt termination of the entire try block. Abrupt termination causes any exception thrown in the try block to be lost, preventing any possible recovery method from handling that specific problem. </p>
        
        <p>In the given program line number <span style="color: red">967 </span> A method invocation <span style="color: red">c.close() </span> is present inside a finally block without a try-catch block </p> 
        <span style="color: #660000">  <h4>Non-compliant Solution</h4></span>
<p> This noncompliant code example contains a finally block that closes the reader object. The programmer incorrectly assumes that the statements in the finally block cannot throw exceptions and consequently fails to appropriately handle any exception that may arise. </p>
 <pre><code class="language-java"> 
 try {
      BufferedReader reader =
          new BufferedReader(new FileReader(some_file));
      try {
        // Do operations
      } finally {
        reader.close();
        // ... Other cleanup code ...
      }
    } catch (IOException x) {
      // Forward to handler
    }
 </code></pre>
<span style="color:#00b33c"><h4>Compliant Solution</h4></span>
<p>  This compliant solution encloses the close() method invocation in a try-catch block of its own within the finally block. Consequently, the potential IOException can be handled without allowing it to propagate further.t</p>
 <pre><code class="language-java"> 
  try {
      BufferedReader reader =
          new BufferedReader(new FileReader(some_file));
      try {
        // Do operations
      } finally {
        try {
          reader.close();
        } catch (IOException ie) {
          // Forward to handler
        }
        // ... Other cleanup code ...
      }
    } catch (IOException x) {
      // Forward to handler
    }
    </code></pre>
<h4>Additional information</h4>
          <ul>
            <li><a href="https://www.securecoding.cert.org/confluence/display/java/ERR05-J.+Do+not+let+checked+exceptions+escape+from+a+finally+block" target="_blank"> ERR05-J. Do not let checked exceptions escape from a finally block</a></li>
          </ul> 
          <h4>Related Guidelines</h4>
          <ul>
            <li><a href="http://cwe.mitre.org/data/definitions/703.html" target="_blank"> CWE-703,</a> Improper Check or Handling of Exceptional Conditions</li>
          <li><a href="http://cwe.mitre.org/data/definitions/248.html" target="_blank"> CWE-248,</a> Uncaught Exception</li>
          
          </ul></td>  </tr>
	  <tr>
		<td>ERR05-J</td>
		<td>CERT</td>
		<td>994</td>
		<td><!--$001violation$001--></td>
	      </tr>
      

<tr>

      
        <td colspan="5">
 <h4>ERR05-J. Do not let checked exceptions escape from a finally block</h4>
     <p>Methods invoked from within a finally block can throw an exception. Failure to catch and handle such exceptions results in the abrupt termination of the entire try block. Abrupt termination causes any exception thrown in the try block to be lost, preventing any possible recovery method from handling that specific problem. </p>
        
        <p>In the given program line number <span style="color: red">994 </span> A method invocation <span style="color: red">c.close() </span> is present inside a finally block without a try-catch block </p> 
        <span style="color: #660000">  <h4>Non-compliant Solution</h4></span>
<p> This noncompliant code example contains a finally block that closes the reader object. The programmer incorrectly assumes that the statements in the finally block cannot throw exceptions and consequently fails to appropriately handle any exception that may arise. </p>
 <pre><code class="language-java"> 
 try {
      BufferedReader reader =
          new BufferedReader(new FileReader(some_file));
      try {
        // Do operations
      } finally {
        reader.close();
        // ... Other cleanup code ...
      }
    } catch (IOException x) {
      // Forward to handler
    }
 </code></pre>
<span style="color:#00b33c"><h4>Compliant Solution</h4></span>
<p>  This compliant solution encloses the close() method invocation in a try-catch block of its own within the finally block. Consequently, the potential IOException can be handled without allowing it to propagate further.t</p>
 <pre><code class="language-java"> 
  try {
      BufferedReader reader =
          new BufferedReader(new FileReader(some_file));
      try {
        // Do operations
      } finally {
        try {
          reader.close();
        } catch (IOException ie) {
          // Forward to handler
        }
        // ... Other cleanup code ...
      }
    } catch (IOException x) {
      // Forward to handler
    }
    </code></pre>
<h4>Additional information</h4>
          <ul>
            <li><a href="https://www.securecoding.cert.org/confluence/display/java/ERR05-J.+Do+not+let+checked+exceptions+escape+from+a+finally+block" target="_blank"> ERR05-J. Do not let checked exceptions escape from a finally block</a></li>
          </ul> 
          <h4>Related Guidelines</h4>
          <ul>
            <li><a href="http://cwe.mitre.org/data/definitions/703.html" target="_blank"> CWE-703,</a> Improper Check or Handling of Exceptional Conditions</li>
          <li><a href="http://cwe.mitre.org/data/definitions/248.html" target="_blank"> CWE-248,</a> Uncaught Exception</li>
          
          </ul></td>  </tr>
	  <tr>
		<td>ERR05-J</td>
		<td>CERT</td>
		<td>1055</td>
		<td><!--$001violation$001--></td>
	      </tr>
      

<tr>

      
        <td colspan="5">
 <h4>ERR05-J. Do not let checked exceptions escape from a finally block</h4>
     <p>Methods invoked from within a finally block can throw an exception. Failure to catch and handle such exceptions results in the abrupt termination of the entire try block. Abrupt termination causes any exception thrown in the try block to be lost, preventing any possible recovery method from handling that specific problem. </p>
        
        <p>In the given program line number <span style="color: red">1055 </span> A method invocation <span style="color: red">c.close() </span> is present inside a finally block without a try-catch block </p> 
        <span style="color: #660000">  <h4>Non-compliant Solution</h4></span>
<p> This noncompliant code example contains a finally block that closes the reader object. The programmer incorrectly assumes that the statements in the finally block cannot throw exceptions and consequently fails to appropriately handle any exception that may arise. </p>
 <pre><code class="language-java"> 
 try {
      BufferedReader reader =
          new BufferedReader(new FileReader(some_file));
      try {
        // Do operations
      } finally {
        reader.close();
        // ... Other cleanup code ...
      }
    } catch (IOException x) {
      // Forward to handler
    }
 </code></pre>
<span style="color:#00b33c"><h4>Compliant Solution</h4></span>
<p>  This compliant solution encloses the close() method invocation in a try-catch block of its own within the finally block. Consequently, the potential IOException can be handled without allowing it to propagate further.t</p>
 <pre><code class="language-java"> 
  try {
      BufferedReader reader =
          new BufferedReader(new FileReader(some_file));
      try {
        // Do operations
      } finally {
        try {
          reader.close();
        } catch (IOException ie) {
          // Forward to handler
        }
        // ... Other cleanup code ...
      }
    } catch (IOException x) {
      // Forward to handler
    }
    </code></pre>
<h4>Additional information</h4>
          <ul>
            <li><a href="https://www.securecoding.cert.org/confluence/display/java/ERR05-J.+Do+not+let+checked+exceptions+escape+from+a+finally+block" target="_blank"> ERR05-J. Do not let checked exceptions escape from a finally block</a></li>
          </ul> 
          <h4>Related Guidelines</h4>
          <ul>
            <li><a href="http://cwe.mitre.org/data/definitions/703.html" target="_blank"> CWE-703,</a> Improper Check or Handling of Exceptional Conditions</li>
          <li><a href="http://cwe.mitre.org/data/definitions/248.html" target="_blank"> CWE-248,</a> Uncaught Exception</li>
          
          </ul></td>  </tr>
<!--$newtableblockattachhere-->
    </tbody>
  </table></div>
      </div>
    </div>

    
 
  <div class="panel panel-default">
      <div class="panel-heading">
        <h4 class="panel-title">
          <a data-toggle="collapse" data-parent="#accordion" href="#Loc42">EasSyncMail.java</a>
        </h4>
      </div>
      <div id="Loc42" class="panel-collapse collapse collapse">
        <div class="panel-body"> <table class="table table-hover table-expandable table-striped">
    <thead>
 <p>Location :<a href="/media/rahul/Education/Project/src/M/Sources/packages/apps/Exchange/src/com/android/exchange/eas/EasSyncMail.java">/media/rahul/Education/Project/src/M/Sources/packages/apps/Exchange/src/com/android/exchange/eas/EasSyncMail.java</a></p>

      <tr>
        <th>Rule</th>
        <th>Standard</th>
        <th>Line number</th>
        
      </tr>
    </thead>
    <tbody>
      
      
   	  <tr>
		<td>ERR05-J</td>
		<td>CERT</td>
		<td>137</td>
		<td><!--$001violation$001--></td>
	      </tr>
      

<tr>

      
        <td colspan="5">
 <h4>ERR05-J. Do not let checked exceptions escape from a finally block</h4>
     <p>Methods invoked from within a finally block can throw an exception. Failure to catch and handle such exceptions results in the abrupt termination of the entire try block. Abrupt termination causes any exception thrown in the try block to be lost, preventing any possible recovery method from handling that specific problem. </p>
        
        <p>In the given program line number <span style="color: red">137 </span> A method invocation <span style="color: red">c.close() </span> is present inside a finally block without a try-catch block </p> 
        <span style="color: #660000">  <h4>Non-compliant Solution</h4></span>
<p> This noncompliant code example contains a finally block that closes the reader object. The programmer incorrectly assumes that the statements in the finally block cannot throw exceptions and consequently fails to appropriately handle any exception that may arise. </p>
 <pre><code class="language-java"> 
 try {
      BufferedReader reader =
          new BufferedReader(new FileReader(some_file));
      try {
        // Do operations
      } finally {
        reader.close();
        // ... Other cleanup code ...
      }
    } catch (IOException x) {
      // Forward to handler
    }
 </code></pre>
<span style="color:#00b33c"><h4>Compliant Solution</h4></span>
<p>  This compliant solution encloses the close() method invocation in a try-catch block of its own within the finally block. Consequently, the potential IOException can be handled without allowing it to propagate further.t</p>
 <pre><code class="language-java"> 
  try {
      BufferedReader reader =
          new BufferedReader(new FileReader(some_file));
      try {
        // Do operations
      } finally {
        try {
          reader.close();
        } catch (IOException ie) {
          // Forward to handler
        }
        // ... Other cleanup code ...
      }
    } catch (IOException x) {
      // Forward to handler
    }
    </code></pre>
<h4>Additional information</h4>
          <ul>
            <li><a href="https://www.securecoding.cert.org/confluence/display/java/ERR05-J.+Do+not+let+checked+exceptions+escape+from+a+finally+block" target="_blank"> ERR05-J. Do not let checked exceptions escape from a finally block</a></li>
          </ul> 
          <h4>Related Guidelines</h4>
          <ul>
            <li><a href="http://cwe.mitre.org/data/definitions/703.html" target="_blank"> CWE-703,</a> Improper Check or Handling of Exceptional Conditions</li>
          <li><a href="http://cwe.mitre.org/data/definitions/248.html" target="_blank"> CWE-248,</a> Uncaught Exception</li>
          
          </ul></td>  </tr>
<!--$newtableblockattachhere-->
    </tbody>
  </table></div>
      </div>
    </div>

    
 
  <div class="panel panel-default">
      <div class="panel-heading">
        <h4 class="panel-title">
          <a data-toggle="collapse" data-parent="#accordion" href="#Loc52">ExchangeDirectoryProvider.java</a>
        </h4>
      </div>
      <div id="Loc52" class="panel-collapse collapse collapse">
        <div class="panel-body"> <table class="table table-hover table-expandable table-striped">
    <thead>
 <p>Location :<a href="/media/rahul/Education/Project/src/M/Sources/packages/apps/Exchange/src/com/android/exchange/provider/ExchangeDirectoryProvider.java">/media/rahul/Education/Project/src/M/Sources/packages/apps/Exchange/src/com/android/exchange/provider/ExchangeDirectoryProvider.java</a></p>

      <tr>
        <th>Rule</th>
        <th>Standard</th>
        <th>Line number</th>
        
      </tr>
    </thead>
    <tbody>
      
      
   	  <tr>
		<td>ERR05-J</td>
		<td>CERT</td>
		<td>352</td>
		<td><!--$001violation$001--></td>
	      </tr>
      

<tr>

      
        <td colspan="5">
 <h4>ERR05-J. Do not let checked exceptions escape from a finally block</h4>
     <p>Methods invoked from within a finally block can throw an exception. Failure to catch and handle such exceptions results in the abrupt termination of the entire try block. Abrupt termination causes any exception thrown in the try block to be lost, preventing any possible recovery method from handling that specific problem. </p>
        
        <p>In the given program line number <span style="color: red">352 </span> A method invocation <span style="color: red">Binder.restoreCallingIdentity(callingId) </span> is present inside a finally block without a try-catch block </p> 
        <span style="color: #660000">  <h4>Non-compliant Solution</h4></span>
<p> This noncompliant code example contains a finally block that closes the reader object. The programmer incorrectly assumes that the statements in the finally block cannot throw exceptions and consequently fails to appropriately handle any exception that may arise. </p>
 <pre><code class="language-java"> 
 try {
      BufferedReader reader =
          new BufferedReader(new FileReader(some_file));
      try {
        // Do operations
      } finally {
        reader.close();
        // ... Other cleanup code ...
      }
    } catch (IOException x) {
      // Forward to handler
    }
 </code></pre>
<span style="color:#00b33c"><h4>Compliant Solution</h4></span>
<p>  This compliant solution encloses the close() method invocation in a try-catch block of its own within the finally block. Consequently, the potential IOException can be handled without allowing it to propagate further.t</p>
 <pre><code class="language-java"> 
  try {
      BufferedReader reader =
          new BufferedReader(new FileReader(some_file));
      try {
        // Do operations
      } finally {
        try {
          reader.close();
        } catch (IOException ie) {
          // Forward to handler
        }
        // ... Other cleanup code ...
      }
    } catch (IOException x) {
      // Forward to handler
    }
    </code></pre>
<h4>Additional information</h4>
          <ul>
            <li><a href="https://www.securecoding.cert.org/confluence/display/java/ERR05-J.+Do+not+let+checked+exceptions+escape+from+a+finally+block" target="_blank"> ERR05-J. Do not let checked exceptions escape from a finally block</a></li>
          </ul> 
          <h4>Related Guidelines</h4>
          <ul>
            <li><a href="http://cwe.mitre.org/data/definitions/703.html" target="_blank"> CWE-703,</a> Improper Check or Handling of Exceptional Conditions</li>
          <li><a href="http://cwe.mitre.org/data/definitions/248.html" target="_blank"> CWE-248,</a> Uncaught Exception</li>
          
          </ul></td>  </tr>
<!--$newtableblockattachhere-->
    </tbody>
  </table></div>
      </div>
    </div>

    
 
  <div class="panel panel-default">
      <div class="panel-heading">
        <h4 class="panel-title">
          <a data-toggle="collapse" data-parent="#accordion" href="#Loc55">CalendarSyncAdapterService.java</a>
        </h4>
      </div>
      <div id="Loc55" class="panel-collapse collapse collapse">
        <div class="panel-body"> <table class="table table-hover table-expandable table-striped">
    <thead>
 <p>Location :<a href="/media/rahul/Education/Project/src/M/Sources/packages/apps/Exchange/src/com/android/exchange/service/CalendarSyncAdapterService.java">/media/rahul/Education/Project/src/M/Sources/packages/apps/Exchange/src/com/android/exchange/service/CalendarSyncAdapterService.java</a></p>

      <tr>
        <th>Rule</th>
        <th>Standard</th>
        <th>Line number</th>
        
      </tr>
    </thead>
    <tbody>
      
      
   	  <tr>
		<td>ERR05-J</td>
		<td>CERT</td>
		<td>108</td>
		<td><!--$001violation$001--></td>
	      </tr>
      

<tr>

      
        <td colspan="5">
 <h4>ERR05-J. Do not let checked exceptions escape from a finally block</h4>
     <p>Methods invoked from within a finally block can throw an exception. Failure to catch and handle such exceptions results in the abrupt termination of the entire try block. Abrupt termination causes any exception thrown in the try block to be lost, preventing any possible recovery method from handling that specific problem. </p>
        
        <p>In the given program line number <span style="color: red">108 </span> A method invocation <span style="color: red">c.close() </span> is present inside a finally block without a try-catch block </p> 
        <span style="color: #660000">  <h4>Non-compliant Solution</h4></span>
<p> This noncompliant code example contains a finally block that closes the reader object. The programmer incorrectly assumes that the statements in the finally block cannot throw exceptions and consequently fails to appropriately handle any exception that may arise. </p>
 <pre><code class="language-java"> 
 try {
      BufferedReader reader =
          new BufferedReader(new FileReader(some_file));
      try {
        // Do operations
      } finally {
        reader.close();
        // ... Other cleanup code ...
      }
    } catch (IOException x) {
      // Forward to handler
    }
 </code></pre>
<span style="color:#00b33c"><h4>Compliant Solution</h4></span>
<p>  This compliant solution encloses the close() method invocation in a try-catch block of its own within the finally block. Consequently, the potential IOException can be handled without allowing it to propagate further.t</p>
 <pre><code class="language-java"> 
  try {
      BufferedReader reader =
          new BufferedReader(new FileReader(some_file));
      try {
        // Do operations
      } finally {
        try {
          reader.close();
        } catch (IOException ie) {
          // Forward to handler
        }
        // ... Other cleanup code ...
      }
    } catch (IOException x) {
      // Forward to handler
    }
    </code></pre>
<h4>Additional information</h4>
          <ul>
            <li><a href="https://www.securecoding.cert.org/confluence/display/java/ERR05-J.+Do+not+let+checked+exceptions+escape+from+a+finally+block" target="_blank"> ERR05-J. Do not let checked exceptions escape from a finally block</a></li>
          </ul> 
          <h4>Related Guidelines</h4>
          <ul>
            <li><a href="http://cwe.mitre.org/data/definitions/703.html" target="_blank"> CWE-703,</a> Improper Check or Handling of Exceptional Conditions</li>
          <li><a href="http://cwe.mitre.org/data/definitions/248.html" target="_blank"> CWE-248,</a> Uncaught Exception</li>
          
          </ul></td>  </tr>
<!--$newtableblockattachhere-->
    </tbody>
  </table></div>
      </div>
    </div>

    
 
  <div class="panel panel-default">
      <div class="panel-heading">
        <h4 class="panel-title">
          <a data-toggle="collapse" data-parent="#accordion" href="#Loc56">ContactsSyncAdapterService.java</a>
        </h4>
      </div>
      <div id="Loc56" class="panel-collapse collapse collapse">
        <div class="panel-body"> <table class="table table-hover table-expandable table-striped">
    <thead>
 <p>Location :<a href="/media/rahul/Education/Project/src/M/Sources/packages/apps/Exchange/src/com/android/exchange/service/ContactsSyncAdapterService.java">/media/rahul/Education/Project/src/M/Sources/packages/apps/Exchange/src/com/android/exchange/service/ContactsSyncAdapterService.java</a></p>

      <tr>
        <th>Rule</th>
        <th>Standard</th>
        <th>Line number</th>
        
      </tr>
    </thead>
    <tbody>
      
      
   	  <tr>
		<td>ERR05-J</td>
		<td>CERT</td>
		<td>157</td>
		<td><!--$001violation$001--></td>
	      </tr>
      

<tr>

      
        <td colspan="5">
 <h4>ERR05-J. Do not let checked exceptions escape from a finally block</h4>
     <p>Methods invoked from within a finally block can throw an exception. Failure to catch and handle such exceptions results in the abrupt termination of the entire try block. Abrupt termination causes any exception thrown in the try block to be lost, preventing any possible recovery method from handling that specific problem. </p>
        
        <p>In the given program line number <span style="color: red">157 </span> A method invocation <span style="color: red">c.close() </span> is present inside a finally block without a try-catch block </p> 
        <span style="color: #660000">  <h4>Non-compliant Solution</h4></span>
<p> This noncompliant code example contains a finally block that closes the reader object. The programmer incorrectly assumes that the statements in the finally block cannot throw exceptions and consequently fails to appropriately handle any exception that may arise. </p>
 <pre><code class="language-java"> 
 try {
      BufferedReader reader =
          new BufferedReader(new FileReader(some_file));
      try {
        // Do operations
      } finally {
        reader.close();
        // ... Other cleanup code ...
      }
    } catch (IOException x) {
      // Forward to handler
    }
 </code></pre>
<span style="color:#00b33c"><h4>Compliant Solution</h4></span>
<p>  This compliant solution encloses the close() method invocation in a try-catch block of its own within the finally block. Consequently, the potential IOException can be handled without allowing it to propagate further.t</p>
 <pre><code class="language-java"> 
  try {
      BufferedReader reader =
          new BufferedReader(new FileReader(some_file));
      try {
        // Do operations
      } finally {
        try {
          reader.close();
        } catch (IOException ie) {
          // Forward to handler
        }
        // ... Other cleanup code ...
      }
    } catch (IOException x) {
      // Forward to handler
    }
    </code></pre>
<h4>Additional information</h4>
          <ul>
            <li><a href="https://www.securecoding.cert.org/confluence/display/java/ERR05-J.+Do+not+let+checked+exceptions+escape+from+a+finally+block" target="_blank"> ERR05-J. Do not let checked exceptions escape from a finally block</a></li>
          </ul> 
          <h4>Related Guidelines</h4>
          <ul>
            <li><a href="http://cwe.mitre.org/data/definitions/703.html" target="_blank"> CWE-703,</a> Improper Check or Handling of Exceptional Conditions</li>
          <li><a href="http://cwe.mitre.org/data/definitions/248.html" target="_blank"> CWE-248,</a> Uncaught Exception</li>
          
          </ul></td>  </tr>
<!--$newtableblockattachhere-->
    </tbody>
  </table></div>
      </div>
    </div>

    
 
  <div class="panel panel-default">
      <div class="panel-heading">
        <h4 class="panel-title">
          <a data-toggle="collapse" data-parent="#accordion" href="#Loc58">EasService.java</a>
        </h4>
      </div>
      <div id="Loc58" class="panel-collapse collapse collapse">
        <div class="panel-body"> <table class="table table-hover table-expandable table-striped">
    <thead>
 <p>Location :<a href="/media/rahul/Education/Project/src/M/Sources/packages/apps/Exchange/src/com/android/exchange/service/EasService.java">/media/rahul/Education/Project/src/M/Sources/packages/apps/Exchange/src/com/android/exchange/service/EasService.java</a></p>

      <tr>
        <th>Rule</th>
        <th>Standard</th>
        <th>Line number</th>
        
      </tr>
    </thead>
    <tbody>
      
      
   	  <tr>
		<td>ERR05-J</td>
		<td>CERT</td>
		<td>314</td>
		<td><!--$001violation$001--></td>
	      </tr>
      

<tr>

      
        <td colspan="5">
 <h4>ERR05-J. Do not let checked exceptions escape from a finally block</h4>
     <p>Methods invoked from within a finally block can throw an exception. Failure to catch and handle such exceptions results in the abrupt termination of the entire try block. Abrupt termination causes any exception thrown in the try block to be lost, preventing any possible recovery method from handling that specific problem. </p>
        
        <p>In the given program line number <span style="color: red">314 </span> A method invocation <span style="color: red">c.close() </span> is present inside a finally block without a try-catch block </p> 
        <span style="color: #660000">  <h4>Non-compliant Solution</h4></span>
<p> This noncompliant code example contains a finally block that closes the reader object. The programmer incorrectly assumes that the statements in the finally block cannot throw exceptions and consequently fails to appropriately handle any exception that may arise. </p>
 <pre><code class="language-java"> 
 try {
      BufferedReader reader =
          new BufferedReader(new FileReader(some_file));
      try {
        // Do operations
      } finally {
        reader.close();
        // ... Other cleanup code ...
      }
    } catch (IOException x) {
      // Forward to handler
    }
 </code></pre>
<span style="color:#00b33c"><h4>Compliant Solution</h4></span>
<p>  This compliant solution encloses the close() method invocation in a try-catch block of its own within the finally block. Consequently, the potential IOException can be handled without allowing it to propagate further.t</p>
 <pre><code class="language-java"> 
  try {
      BufferedReader reader =
          new BufferedReader(new FileReader(some_file));
      try {
        // Do operations
      } finally {
        try {
          reader.close();
        } catch (IOException ie) {
          // Forward to handler
        }
        // ... Other cleanup code ...
      }
    } catch (IOException x) {
      // Forward to handler
    }
    </code></pre>
<h4>Additional information</h4>
          <ul>
            <li><a href="https://www.securecoding.cert.org/confluence/display/java/ERR05-J.+Do+not+let+checked+exceptions+escape+from+a+finally+block" target="_blank"> ERR05-J. Do not let checked exceptions escape from a finally block</a></li>
          </ul> 
          <h4>Related Guidelines</h4>
          <ul>
            <li><a href="http://cwe.mitre.org/data/definitions/703.html" target="_blank"> CWE-703,</a> Improper Check or Handling of Exceptional Conditions</li>
          <li><a href="http://cwe.mitre.org/data/definitions/248.html" target="_blank"> CWE-248,</a> Uncaught Exception</li>
          
          </ul></td>  </tr>
	  <tr>
		<td>ERR05-J</td>
		<td>CERT</td>
		<td>406</td>
		<td><!--$001violation$001--></td>
	      </tr>
      

<tr>

      
        <td colspan="5">
 <h4>ERR05-J. Do not let checked exceptions escape from a finally block</h4>
     <p>Methods invoked from within a finally block can throw an exception. Failure to catch and handle such exceptions results in the abrupt termination of the entire try block. Abrupt termination causes any exception thrown in the try block to be lost, preventing any possible recovery method from handling that specific problem. </p>
        
        <p>In the given program line number <span style="color: red">406 </span> A method invocation <span style="color: red">operation.getAccount() </span> is present inside a finally block without a try-catch block </p> 
        <span style="color: #660000">  <h4>Non-compliant Solution</h4></span>
<p> This noncompliant code example contains a finally block that closes the reader object. The programmer incorrectly assumes that the statements in the finally block cannot throw exceptions and consequently fails to appropriately handle any exception that may arise. </p>
 <pre><code class="language-java"> 
 try {
      BufferedReader reader =
          new BufferedReader(new FileReader(some_file));
      try {
        // Do operations
      } finally {
        reader.close();
        // ... Other cleanup code ...
      }
    } catch (IOException x) {
      // Forward to handler
    }
 </code></pre>
<span style="color:#00b33c"><h4>Compliant Solution</h4></span>
<p>  This compliant solution encloses the close() method invocation in a try-catch block of its own within the finally block. Consequently, the potential IOException can be handled without allowing it to propagate further.t</p>
 <pre><code class="language-java"> 
  try {
      BufferedReader reader =
          new BufferedReader(new FileReader(some_file));
      try {
        // Do operations
      } finally {
        try {
          reader.close();
        } catch (IOException ie) {
          // Forward to handler
        }
        // ... Other cleanup code ...
      }
    } catch (IOException x) {
      // Forward to handler
    }
    </code></pre>
<h4>Additional information</h4>
          <ul>
            <li><a href="https://www.securecoding.cert.org/confluence/display/java/ERR05-J.+Do+not+let+checked+exceptions+escape+from+a+finally+block" target="_blank"> ERR05-J. Do not let checked exceptions escape from a finally block</a></li>
          </ul> 
          <h4>Related Guidelines</h4>
          <ul>
            <li><a href="http://cwe.mitre.org/data/definitions/703.html" target="_blank"> CWE-703,</a> Improper Check or Handling of Exceptional Conditions</li>
          <li><a href="http://cwe.mitre.org/data/definitions/248.html" target="_blank"> CWE-248,</a> Uncaught Exception</li>
          
          </ul></td>  </tr>
	  <tr>
		<td>ERR05-J</td>
		<td>CERT</td>
		<td>462</td>
		<td><!--$001violation$001--></td>
	      </tr>
      

<tr>

      
        <td colspan="5">
 <h4>ERR05-J. Do not let checked exceptions escape from a finally block</h4>
     <p>Methods invoked from within a finally block can throw an exception. Failure to catch and handle such exceptions results in the abrupt termination of the entire try block. Abrupt termination causes any exception thrown in the try block to be lost, preventing any possible recovery method from handling that specific problem. </p>
        
        <p>In the given program line number <span style="color: red">462 </span> A method invocation <span style="color: red">c.close() </span> is present inside a finally block without a try-catch block </p> 
        <span style="color: #660000">  <h4>Non-compliant Solution</h4></span>
<p> This noncompliant code example contains a finally block that closes the reader object. The programmer incorrectly assumes that the statements in the finally block cannot throw exceptions and consequently fails to appropriately handle any exception that may arise. </p>
 <pre><code class="language-java"> 
 try {
      BufferedReader reader =
          new BufferedReader(new FileReader(some_file));
      try {
        // Do operations
      } finally {
        reader.close();
        // ... Other cleanup code ...
      }
    } catch (IOException x) {
      // Forward to handler
    }
 </code></pre>
<span style="color:#00b33c"><h4>Compliant Solution</h4></span>
<p>  This compliant solution encloses the close() method invocation in a try-catch block of its own within the finally block. Consequently, the potential IOException can be handled without allowing it to propagate further.t</p>
 <pre><code class="language-java"> 
  try {
      BufferedReader reader =
          new BufferedReader(new FileReader(some_file));
      try {
        // Do operations
      } finally {
        try {
          reader.close();
        } catch (IOException ie) {
          // Forward to handler
        }
        // ... Other cleanup code ...
      }
    } catch (IOException x) {
      // Forward to handler
    }
    </code></pre>
<h4>Additional information</h4>
          <ul>
            <li><a href="https://www.securecoding.cert.org/confluence/display/java/ERR05-J.+Do+not+let+checked+exceptions+escape+from+a+finally+block" target="_blank"> ERR05-J. Do not let checked exceptions escape from a finally block</a></li>
          </ul> 
          <h4>Related Guidelines</h4>
          <ul>
            <li><a href="http://cwe.mitre.org/data/definitions/703.html" target="_blank"> CWE-703,</a> Improper Check or Handling of Exceptional Conditions</li>
          <li><a href="http://cwe.mitre.org/data/definitions/248.html" target="_blank"> CWE-248,</a> Uncaught Exception</li>
          
          </ul></td>  </tr>
<!--$newtableblockattachhere-->
    </tbody>
  </table></div>
      </div>
    </div>

    
 
  <div class="panel panel-default">
      <div class="panel-heading">
        <h4 class="panel-title">
          <a data-toggle="collapse" data-parent="#accordion" href="#Loc60">PingSyncSynchronizer.java</a>
        </h4>
      </div>
      <div id="Loc60" class="panel-collapse collapse collapse">
        <div class="panel-body"> <table class="table table-hover table-expandable table-striped">
    <thead>
 <p>Location :<a href="/media/rahul/Education/Project/src/M/Sources/packages/apps/Exchange/src/com/android/exchange/service/PingSyncSynchronizer.java">/media/rahul/Education/Project/src/M/Sources/packages/apps/Exchange/src/com/android/exchange/service/PingSyncSynchronizer.java</a></p>

      <tr>
        <th>Rule</th>
        <th>Standard</th>
        <th>Line number</th>
        
      </tr>
    </thead>
    <tbody>
      
      
   	  <tr>
		<td>ERR05-J</td>
		<td>CERT</td>
		<td>372</td>
		<td><!--$001violation$001--></td>
	      </tr>
      

<tr>

      
        <td colspan="5">
 <h4>ERR05-J. Do not let checked exceptions escape from a finally block</h4>
     <p>Methods invoked from within a finally block can throw an exception. Failure to catch and handle such exceptions results in the abrupt termination of the entire try block. Abrupt termination causes any exception thrown in the try block to be lost, preventing any possible recovery method from handling that specific problem. </p>
        
        <p>In the given program line number <span style="color: red">372 </span> A method invocation <span style="color: red">mLock.unlock() </span> is present inside a finally block without a try-catch block </p> 
        <span style="color: #660000">  <h4>Non-compliant Solution</h4></span>
<p> This noncompliant code example contains a finally block that closes the reader object. The programmer incorrectly assumes that the statements in the finally block cannot throw exceptions and consequently fails to appropriately handle any exception that may arise. </p>
 <pre><code class="language-java"> 
 try {
      BufferedReader reader =
          new BufferedReader(new FileReader(some_file));
      try {
        // Do operations
      } finally {
        reader.close();
        // ... Other cleanup code ...
      }
    } catch (IOException x) {
      // Forward to handler
    }
 </code></pre>
<span style="color:#00b33c"><h4>Compliant Solution</h4></span>
<p>  This compliant solution encloses the close() method invocation in a try-catch block of its own within the finally block. Consequently, the potential IOException can be handled without allowing it to propagate further.t</p>
 <pre><code class="language-java"> 
  try {
      BufferedReader reader =
          new BufferedReader(new FileReader(some_file));
      try {
        // Do operations
      } finally {
        try {
          reader.close();
        } catch (IOException ie) {
          // Forward to handler
        }
        // ... Other cleanup code ...
      }
    } catch (IOException x) {
      // Forward to handler
    }
    </code></pre>
<h4>Additional information</h4>
          <ul>
            <li><a href="https://www.securecoding.cert.org/confluence/display/java/ERR05-J.+Do+not+let+checked+exceptions+escape+from+a+finally+block" target="_blank"> ERR05-J. Do not let checked exceptions escape from a finally block</a></li>
          </ul> 
          <h4>Related Guidelines</h4>
          <ul>
            <li><a href="http://cwe.mitre.org/data/definitions/703.html" target="_blank"> CWE-703,</a> Improper Check or Handling of Exceptional Conditions</li>
          <li><a href="http://cwe.mitre.org/data/definitions/248.html" target="_blank"> CWE-248,</a> Uncaught Exception</li>
          
          </ul></td>  </tr>
	  <tr>
		<td>ERR05-J</td>
		<td>CERT</td>
		<td>390</td>
		<td><!--$001violation$001--></td>
	      </tr>
      

<tr>

      
        <td colspan="5">
 <h4>ERR05-J. Do not let checked exceptions escape from a finally block</h4>
     <p>Methods invoked from within a finally block can throw an exception. Failure to catch and handle such exceptions results in the abrupt termination of the entire try block. Abrupt termination causes any exception thrown in the try block to be lost, preventing any possible recovery method from handling that specific problem. </p>
        
        <p>In the given program line number <span style="color: red">390 </span> A method invocation <span style="color: red">mLock.unlock() </span> is present inside a finally block without a try-catch block </p> 
        <span style="color: #660000">  <h4>Non-compliant Solution</h4></span>
<p> This noncompliant code example contains a finally block that closes the reader object. The programmer incorrectly assumes that the statements in the finally block cannot throw exceptions and consequently fails to appropriately handle any exception that may arise. </p>
 <pre><code class="language-java"> 
 try {
      BufferedReader reader =
          new BufferedReader(new FileReader(some_file));
      try {
        // Do operations
      } finally {
        reader.close();
        // ... Other cleanup code ...
      }
    } catch (IOException x) {
      // Forward to handler
    }
 </code></pre>
<span style="color:#00b33c"><h4>Compliant Solution</h4></span>
<p>  This compliant solution encloses the close() method invocation in a try-catch block of its own within the finally block. Consequently, the potential IOException can be handled without allowing it to propagate further.t</p>
 <pre><code class="language-java"> 
  try {
      BufferedReader reader =
          new BufferedReader(new FileReader(some_file));
      try {
        // Do operations
      } finally {
        try {
          reader.close();
        } catch (IOException ie) {
          // Forward to handler
        }
        // ... Other cleanup code ...
      }
    } catch (IOException x) {
      // Forward to handler
    }
    </code></pre>
<h4>Additional information</h4>
          <ul>
            <li><a href="https://www.securecoding.cert.org/confluence/display/java/ERR05-J.+Do+not+let+checked+exceptions+escape+from+a+finally+block" target="_blank"> ERR05-J. Do not let checked exceptions escape from a finally block</a></li>
          </ul> 
          <h4>Related Guidelines</h4>
          <ul>
            <li><a href="http://cwe.mitre.org/data/definitions/703.html" target="_blank"> CWE-703,</a> Improper Check or Handling of Exceptional Conditions</li>
          <li><a href="http://cwe.mitre.org/data/definitions/248.html" target="_blank"> CWE-248,</a> Uncaught Exception</li>
          
          </ul></td>  </tr>
	  <tr>
		<td>ERR05-J</td>
		<td>CERT</td>
		<td>407</td>
		<td><!--$001violation$001--></td>
	      </tr>
      

<tr>

      
        <td colspan="5">
 <h4>ERR05-J. Do not let checked exceptions escape from a finally block</h4>
     <p>Methods invoked from within a finally block can throw an exception. Failure to catch and handle such exceptions results in the abrupt termination of the entire try block. Abrupt termination causes any exception thrown in the try block to be lost, preventing any possible recovery method from handling that specific problem. </p>
        
        <p>In the given program line number <span style="color: red">407 </span> A method invocation <span style="color: red">mLock.unlock() </span> is present inside a finally block without a try-catch block </p> 
        <span style="color: #660000">  <h4>Non-compliant Solution</h4></span>
<p> This noncompliant code example contains a finally block that closes the reader object. The programmer incorrectly assumes that the statements in the finally block cannot throw exceptions and consequently fails to appropriately handle any exception that may arise. </p>
 <pre><code class="language-java"> 
 try {
      BufferedReader reader =
          new BufferedReader(new FileReader(some_file));
      try {
        // Do operations
      } finally {
        reader.close();
        // ... Other cleanup code ...
      }
    } catch (IOException x) {
      // Forward to handler
    }
 </code></pre>
<span style="color:#00b33c"><h4>Compliant Solution</h4></span>
<p>  This compliant solution encloses the close() method invocation in a try-catch block of its own within the finally block. Consequently, the potential IOException can be handled without allowing it to propagate further.t</p>
 <pre><code class="language-java"> 
  try {
      BufferedReader reader =
          new BufferedReader(new FileReader(some_file));
      try {
        // Do operations
      } finally {
        try {
          reader.close();
        } catch (IOException ie) {
          // Forward to handler
        }
        // ... Other cleanup code ...
      }
    } catch (IOException x) {
      // Forward to handler
    }
    </code></pre>
<h4>Additional information</h4>
          <ul>
            <li><a href="https://www.securecoding.cert.org/confluence/display/java/ERR05-J.+Do+not+let+checked+exceptions+escape+from+a+finally+block" target="_blank"> ERR05-J. Do not let checked exceptions escape from a finally block</a></li>
          </ul> 
          <h4>Related Guidelines</h4>
          <ul>
            <li><a href="http://cwe.mitre.org/data/definitions/703.html" target="_blank"> CWE-703,</a> Improper Check or Handling of Exceptional Conditions</li>
          <li><a href="http://cwe.mitre.org/data/definitions/248.html" target="_blank"> CWE-248,</a> Uncaught Exception</li>
          
          </ul></td>  </tr>
	  <tr>
		<td>ERR05-J</td>
		<td>CERT</td>
		<td>419</td>
		<td><!--$001violation$001--></td>
	      </tr>
      

<tr>

      
        <td colspan="5">
 <h4>ERR05-J. Do not let checked exceptions escape from a finally block</h4>
     <p>Methods invoked from within a finally block can throw an exception. Failure to catch and handle such exceptions results in the abrupt termination of the entire try block. Abrupt termination causes any exception thrown in the try block to be lost, preventing any possible recovery method from handling that specific problem. </p>
        
        <p>In the given program line number <span style="color: red">419 </span> A method invocation <span style="color: red">mLock.unlock() </span> is present inside a finally block without a try-catch block </p> 
        <span style="color: #660000">  <h4>Non-compliant Solution</h4></span>
<p> This noncompliant code example contains a finally block that closes the reader object. The programmer incorrectly assumes that the statements in the finally block cannot throw exceptions and consequently fails to appropriately handle any exception that may arise. </p>
 <pre><code class="language-java"> 
 try {
      BufferedReader reader =
          new BufferedReader(new FileReader(some_file));
      try {
        // Do operations
      } finally {
        reader.close();
        // ... Other cleanup code ...
      }
    } catch (IOException x) {
      // Forward to handler
    }
 </code></pre>
<span style="color:#00b33c"><h4>Compliant Solution</h4></span>
<p>  This compliant solution encloses the close() method invocation in a try-catch block of its own within the finally block. Consequently, the potential IOException can be handled without allowing it to propagate further.t</p>
 <pre><code class="language-java"> 
  try {
      BufferedReader reader =
          new BufferedReader(new FileReader(some_file));
      try {
        // Do operations
      } finally {
        try {
          reader.close();
        } catch (IOException ie) {
          // Forward to handler
        }
        // ... Other cleanup code ...
      }
    } catch (IOException x) {
      // Forward to handler
    }
    </code></pre>
<h4>Additional information</h4>
          <ul>
            <li><a href="https://www.securecoding.cert.org/confluence/display/java/ERR05-J.+Do+not+let+checked+exceptions+escape+from+a+finally+block" target="_blank"> ERR05-J. Do not let checked exceptions escape from a finally block</a></li>
          </ul> 
          <h4>Related Guidelines</h4>
          <ul>
            <li><a href="http://cwe.mitre.org/data/definitions/703.html" target="_blank"> CWE-703,</a> Improper Check or Handling of Exceptional Conditions</li>
          <li><a href="http://cwe.mitre.org/data/definitions/248.html" target="_blank"> CWE-248,</a> Uncaught Exception</li>
          
          </ul></td>  </tr>
	  <tr>
		<td>ERR05-J</td>
		<td>CERT</td>
		<td>432</td>
		<td><!--$001violation$001--></td>
	      </tr>
      

<tr>

      
        <td colspan="5">
 <h4>ERR05-J. Do not let checked exceptions escape from a finally block</h4>
     <p>Methods invoked from within a finally block can throw an exception. Failure to catch and handle such exceptions results in the abrupt termination of the entire try block. Abrupt termination causes any exception thrown in the try block to be lost, preventing any possible recovery method from handling that specific problem. </p>
        
        <p>In the given program line number <span style="color: red">432 </span> A method invocation <span style="color: red">mLock.unlock() </span> is present inside a finally block without a try-catch block </p> 
        <span style="color: #660000">  <h4>Non-compliant Solution</h4></span>
<p> This noncompliant code example contains a finally block that closes the reader object. The programmer incorrectly assumes that the statements in the finally block cannot throw exceptions and consequently fails to appropriately handle any exception that may arise. </p>
 <pre><code class="language-java"> 
 try {
      BufferedReader reader =
          new BufferedReader(new FileReader(some_file));
      try {
        // Do operations
      } finally {
        reader.close();
        // ... Other cleanup code ...
      }
    } catch (IOException x) {
      // Forward to handler
    }
 </code></pre>
<span style="color:#00b33c"><h4>Compliant Solution</h4></span>
<p>  This compliant solution encloses the close() method invocation in a try-catch block of its own within the finally block. Consequently, the potential IOException can be handled without allowing it to propagate further.t</p>
 <pre><code class="language-java"> 
  try {
      BufferedReader reader =
          new BufferedReader(new FileReader(some_file));
      try {
        // Do operations
      } finally {
        try {
          reader.close();
        } catch (IOException ie) {
          // Forward to handler
        }
        // ... Other cleanup code ...
      }
    } catch (IOException x) {
      // Forward to handler
    }
    </code></pre>
<h4>Additional information</h4>
          <ul>
            <li><a href="https://www.securecoding.cert.org/confluence/display/java/ERR05-J.+Do+not+let+checked+exceptions+escape+from+a+finally+block" target="_blank"> ERR05-J. Do not let checked exceptions escape from a finally block</a></li>
          </ul> 
          <h4>Related Guidelines</h4>
          <ul>
            <li><a href="http://cwe.mitre.org/data/definitions/703.html" target="_blank"> CWE-703,</a> Improper Check or Handling of Exceptional Conditions</li>
          <li><a href="http://cwe.mitre.org/data/definitions/248.html" target="_blank"> CWE-248,</a> Uncaught Exception</li>
          
          </ul></td>  </tr>
	  <tr>
		<td>ERR05-J</td>
		<td>CERT</td>
		<td>448</td>
		<td><!--$001violation$001--></td>
	      </tr>
      

<tr>

      
        <td colspan="5">
 <h4>ERR05-J. Do not let checked exceptions escape from a finally block</h4>
     <p>Methods invoked from within a finally block can throw an exception. Failure to catch and handle such exceptions results in the abrupt termination of the entire try block. Abrupt termination causes any exception thrown in the try block to be lost, preventing any possible recovery method from handling that specific problem. </p>
        
        <p>In the given program line number <span style="color: red">448 </span> A method invocation <span style="color: red">mLock.unlock() </span> is present inside a finally block without a try-catch block </p> 
        <span style="color: #660000">  <h4>Non-compliant Solution</h4></span>
<p> This noncompliant code example contains a finally block that closes the reader object. The programmer incorrectly assumes that the statements in the finally block cannot throw exceptions and consequently fails to appropriately handle any exception that may arise. </p>
 <pre><code class="language-java"> 
 try {
      BufferedReader reader =
          new BufferedReader(new FileReader(some_file));
      try {
        // Do operations
      } finally {
        reader.close();
        // ... Other cleanup code ...
      }
    } catch (IOException x) {
      // Forward to handler
    }
 </code></pre>
<span style="color:#00b33c"><h4>Compliant Solution</h4></span>
<p>  This compliant solution encloses the close() method invocation in a try-catch block of its own within the finally block. Consequently, the potential IOException can be handled without allowing it to propagate further.t</p>
 <pre><code class="language-java"> 
  try {
      BufferedReader reader =
          new BufferedReader(new FileReader(some_file));
      try {
        // Do operations
      } finally {
        try {
          reader.close();
        } catch (IOException ie) {
          // Forward to handler
        }
        // ... Other cleanup code ...
      }
    } catch (IOException x) {
      // Forward to handler
    }
    </code></pre>
<h4>Additional information</h4>
          <ul>
            <li><a href="https://www.securecoding.cert.org/confluence/display/java/ERR05-J.+Do+not+let+checked+exceptions+escape+from+a+finally+block" target="_blank"> ERR05-J. Do not let checked exceptions escape from a finally block</a></li>
          </ul> 
          <h4>Related Guidelines</h4>
          <ul>
            <li><a href="http://cwe.mitre.org/data/definitions/703.html" target="_blank"> CWE-703,</a> Improper Check or Handling of Exceptional Conditions</li>
          <li><a href="http://cwe.mitre.org/data/definitions/248.html" target="_blank"> CWE-248,</a> Uncaught Exception</li>
          
          </ul></td>  </tr>
	  <tr>
		<td>ERR05-J</td>
		<td>CERT</td>
		<td>462</td>
		<td><!--$001violation$001--></td>
	      </tr>
      

<tr>

      
        <td colspan="5">
 <h4>ERR05-J. Do not let checked exceptions escape from a finally block</h4>
     <p>Methods invoked from within a finally block can throw an exception. Failure to catch and handle such exceptions results in the abrupt termination of the entire try block. Abrupt termination causes any exception thrown in the try block to be lost, preventing any possible recovery method from handling that specific problem. </p>
        
        <p>In the given program line number <span style="color: red">462 </span> A method invocation <span style="color: red">mLock.unlock() </span> is present inside a finally block without a try-catch block </p> 
        <span style="color: #660000">  <h4>Non-compliant Solution</h4></span>
<p> This noncompliant code example contains a finally block that closes the reader object. The programmer incorrectly assumes that the statements in the finally block cannot throw exceptions and consequently fails to appropriately handle any exception that may arise. </p>
 <pre><code class="language-java"> 
 try {
      BufferedReader reader =
          new BufferedReader(new FileReader(some_file));
      try {
        // Do operations
      } finally {
        reader.close();
        // ... Other cleanup code ...
      }
    } catch (IOException x) {
      // Forward to handler
    }
 </code></pre>
<span style="color:#00b33c"><h4>Compliant Solution</h4></span>
<p>  This compliant solution encloses the close() method invocation in a try-catch block of its own within the finally block. Consequently, the potential IOException can be handled without allowing it to propagate further.t</p>
 <pre><code class="language-java"> 
  try {
      BufferedReader reader =
          new BufferedReader(new FileReader(some_file));
      try {
        // Do operations
      } finally {
        try {
          reader.close();
        } catch (IOException ie) {
          // Forward to handler
        }
        // ... Other cleanup code ...
      }
    } catch (IOException x) {
      // Forward to handler
    }
    </code></pre>
<h4>Additional information</h4>
          <ul>
            <li><a href="https://www.securecoding.cert.org/confluence/display/java/ERR05-J.+Do+not+let+checked+exceptions+escape+from+a+finally+block" target="_blank"> ERR05-J. Do not let checked exceptions escape from a finally block</a></li>
          </ul> 
          <h4>Related Guidelines</h4>
          <ul>
            <li><a href="http://cwe.mitre.org/data/definitions/703.html" target="_blank"> CWE-703,</a> Improper Check or Handling of Exceptional Conditions</li>
          <li><a href="http://cwe.mitre.org/data/definitions/248.html" target="_blank"> CWE-248,</a> Uncaught Exception</li>
          
          </ul></td>  </tr>
<!--$newtableblockattachhere-->
    </tbody>
  </table></div>
      </div>
    </div>

    
 
  <div class="panel panel-default">
      <div class="panel-heading">
        <h4 class="panel-title">
          <a data-toggle="collapse" data-parent="#accordion" href="#Loc64">CalendarUtilities.java</a>
        </h4>
      </div>
      <div id="Loc64" class="panel-collapse collapse collapse">
        <div class="panel-body"> <table class="table table-hover table-expandable table-striped">
    <thead>
 <p>Location :<a href="/media/rahul/Education/Project/src/M/Sources/packages/apps/Exchange/src/com/android/exchange/utility/CalendarUtilities.java">/media/rahul/Education/Project/src/M/Sources/packages/apps/Exchange/src/com/android/exchange/utility/CalendarUtilities.java</a></p>

      <tr>
        <th>Rule</th>
        <th>Standard</th>
        <th>Line number</th>
        
      </tr>
    </thead>
    <tbody>
      
      
   	  <tr>
		<td>ERR05-J</td>
		<td>CERT</td>
		<td>2070</td>
		<td><!--$001violation$001--></td>
	      </tr>
      

<tr>

      
        <td colspan="5">
 <h4>ERR05-J. Do not let checked exceptions escape from a finally block</h4>
     <p>Methods invoked from within a finally block can throw an exception. Failure to catch and handle such exceptions results in the abrupt termination of the entire try block. Abrupt termination causes any exception thrown in the try block to be lost, preventing any possible recovery method from handling that specific problem. </p>
        
        <p>In the given program line number <span style="color: red">2070 </span> A method invocation <span style="color: red">eventIterator.close() </span> is present inside a finally block without a try-catch block </p> 
        <span style="color: #660000">  <h4>Non-compliant Solution</h4></span>
<p> This noncompliant code example contains a finally block that closes the reader object. The programmer incorrectly assumes that the statements in the finally block cannot throw exceptions and consequently fails to appropriately handle any exception that may arise. </p>
 <pre><code class="language-java"> 
 try {
      BufferedReader reader =
          new BufferedReader(new FileReader(some_file));
      try {
        // Do operations
      } finally {
        reader.close();
        // ... Other cleanup code ...
      }
    } catch (IOException x) {
      // Forward to handler
    }
 </code></pre>
<span style="color:#00b33c"><h4>Compliant Solution</h4></span>
<p>  This compliant solution encloses the close() method invocation in a try-catch block of its own within the finally block. Consequently, the potential IOException can be handled without allowing it to propagate further.t</p>
 <pre><code class="language-java"> 
  try {
      BufferedReader reader =
          new BufferedReader(new FileReader(some_file));
      try {
        // Do operations
      } finally {
        try {
          reader.close();
        } catch (IOException ie) {
          // Forward to handler
        }
        // ... Other cleanup code ...
      }
    } catch (IOException x) {
      // Forward to handler
    }
    </code></pre>
<h4>Additional information</h4>
          <ul>
            <li><a href="https://www.securecoding.cert.org/confluence/display/java/ERR05-J.+Do+not+let+checked+exceptions+escape+from+a+finally+block" target="_blank"> ERR05-J. Do not let checked exceptions escape from a finally block</a></li>
          </ul> 
          <h4>Related Guidelines</h4>
          <ul>
            <li><a href="http://cwe.mitre.org/data/definitions/703.html" target="_blank"> CWE-703,</a> Improper Check or Handling of Exceptional Conditions</li>
          <li><a href="http://cwe.mitre.org/data/definitions/248.html" target="_blank"> CWE-248,</a> Uncaught Exception</li>
          
          </ul></td>  </tr>
<!--$newtableblockattachhere-->
    </tbody>
  </table></div>
      </div>
    </div>

    
 
  <div class="panel panel-default">
      <div class="panel-heading">
        <h4 class="panel-title">
          <a data-toggle="collapse" data-parent="#accordion" href="#Loc66">FileLogger.java</a>
        </h4>
      </div>
      <div id="Loc66" class="panel-collapse collapse collapse">
        <div class="panel-body"> <table class="table table-hover table-expandable table-striped">
    <thead>
 <p>Location :<a href="/media/rahul/Education/Project/src/M/Sources/packages/apps/Exchange/src/com/android/exchange/utility/FileLogger.java">/media/rahul/Education/Project/src/M/Sources/packages/apps/Exchange/src/com/android/exchange/utility/FileLogger.java</a></p>

      <tr>
        <th>Rule</th>
        <th>Standard</th>
        <th>Line number</th>
        
      </tr>
    </thead>
    <tbody>
      
      
   	  <tr>
		<td>DCL00-J</td>
		<td>CERT</td>
		<td>39</td>
		<td><!--$001violation$001--></td>
	      </tr>
      

<tr>

      
        <td colspan="5">
 <h4>DCL00-J. Prevent class initialization cycles</h4>
     <p>Initialization of a class consists of executing its static initializers and the initializers for static fields (class variables) declared in the class. Therefore, the presence of a static field triggers the initialization of a class. However, the initializer of a static field could depend on the initialization of another class, possibly creating an initialization cycle.\cite{CERT}. There are two types of class initialization cycle problem, Intraclass and interclass. In intraclass the vulnerability  happened because the constructor invocation is done before completing the initialization of the variables. The solution is, do the object creation after the complete variable initialization.</p>
        
        <p>In the given program line number <span style="color: red">39 </span> have DCL00-J because <span style="color: red"> 'Static' constructor initialization at line 27, invoked at line  39 and variable ' LOG_FILE_NAME ' initialization at line 29. Please do 'static' constructor initialization after all 'static' variable initialization </span> trying to </p> 
        <span style="color: #660000">  <h4>Non-compliant Solution</h4></span>
<p> In the non-compliant code, there is a static final variable initialization after class object creation. </p>
 <pre><code class="language-java"> 
public class RollNo {
private final int idNumber;
private static final RollNo r= new RollNo();
private static final int seed = (int) (Math.random() * 100);
public RollNo() {
idNumber = seed - 10;
}
public static void main(String[] args) {
System.out.println("Your unique id is: " + r.idNumber);
}
}
 </code></pre>
<span style="color:#00b33c"><h4>Compliant Solution</h4></span>
<p>  In the compliant code, the static final variable initialization done before class object creation.</p>
 <pre><code class="language-java"> 
public class RollNo {
private final int idNumber;
private static final int seed = (int) (Math.random() * 100);
private static final RollNo r= new RollNo();
public RollNo() {
idNumber = seed - 10;
}
public static void main(String[] args) {
System.out.println("Your unique id is: " + r.idNumber);
}
}
 </code></pre>
<h4>Additional information</h4>
          <ul>
            <li><a href="https://www.securecoding.cert.org/confluence/display/java/DCL00-J.+Prevent+class+initialization+cycles" target="_blank">DCL00-J. Prevent class initialization cycles</a></li>
          </ul> 
          <h4>Related Guidelines</h4>
          <ul>
            <li><a href="https://www.securecoding.cert.org/confluence/pages/viewpage.action?pageId=637" target="_blank"> DCL14-CPP. Avoid assumptions about the initialization order between translation units</a></li>
          <li><a href="http://cwe.mitre.org/data/definitions/665.html" target="_blank">CWE-665,</a> Improper Initialization</li>
          
          </ul></td>  </tr>
<!--$newtableblockattachhere-->
    </tbody>
  </table></div>
      </div>
    </div>

    
 
 <!--$newfileblockattachhere-->
    
  </div> 
</div>
</div>   
<br>
<br>
<br>
<br>
<br>
</body>
</html>

